Workbook

Sheet Sheet9
B4: Main Villa
B5: 1. Main Villa
B6: 2. MEP/BINT
B8: MULTIPURPOSE BLOCK & EXTERNAL WORKS
B9: 1. Compund Wall
B10: 2. Multipurpose Room

Sheet Level Cal
E3: DMD Level | F3: Design Level
D6: Gate Level | E6: =3.55+0.3 -> 3.85 | F6: 0 | G6: As per Setting out Plan Drg Ref, 30cm above road level
D8: Asphalt Road | E8: 3.55
B10: 3.425 | D10: OGL | E10: =N12 -> 3.72 | F10: =-(E6-E10) -> -0.13 | G10: As per the survey Report
L11: Points inside the Plot | M11: Min | N11: 3.13
D12: Foundation Level | E12: 2.35 | F12: =-(E6-E12) -> -1.5 | M12: Max | N12: 3.72
D14: PCC Level | E14: =E12-0.1 -> 2.25 | F14: =-(E6-E14) -> -1.6 | G14: PCC + Blinding 50mm | M14: OGL | N14: =SUM(N11:N12)/2 -> 3.425
D16: No Road Base
M17: Water Table
D18: Water Tank | E18: =E8-3.95 -> -0.4 | F18: =-(E6-E18) -> -4.25 | G18: Water Tank Footing level(-3.95)
Y19: WATER TANK
Y20: As per Sectional Plan
I21: =E10-E12 -> 1.37 | Y21: 1.5 | Z21: height
I22: =E6-E12 -> 1.5 | Y22: 0.5
D23: Water Table | E23: 0.6 | F23: =-(E6-E23) -> -3.25 | Y23: 1
Y24: 0.1
Y25: 0.2 | Z25: Top Slab
E26: =E12-0.25 -> 2.1 | Y26: 0.5 | Z26: Bottom Slab/Raft
Y27: =SUM(Y21:Y26) -> 3.8 | Z27: Depth
E28: =E6-3.6 -> 0.25
Y29: As per Structural Plan
E30: DMD Level | F30: Design Level | Y30: -3.1 | Z30: SSL
Y31: -0.5 | Z31: Raft Thickness
Y32: =Y30+Y31 -> -3.6 | Z32: Depth
D33: Gate Level | E33: =3.55+0.3 -> 3.85 | F33: 0 | Y33: 0.05 | Z33: Protection Screed
Y34: 0.05 | Z34: Blinding
D35: Asphalt Road | E35: 3.55 | Y35: 0.25 | Z35: Road Base
Y36: =Y32+-SUM(Y33:Y35) -> -3.95 | Z36: Total Depth
D37: OGL | E37: =+E10 -> 3.72 | F37: =-(E33-E37) -> -0.13
D39: Foundation Level | E39: 2.35 | F39: =-(E33-E39) -> -1.5
D41: PCC Level | E41: =E39-0.1 -> 2.25 | F41: =-(E33-E41) -> -1.6
D43: No Road Base
D45: Water Tank | E45: =E35-3.95 -> -0.4 | F45: =-(E33-E45) -> -4.25
D50: Water Table | E50: 0.6 | F50: =-(E33-E50) -> -3.25

Sheet SITE WORK 
A2: Project : | B2: VILLA 5SQ-A
A3: Employer : | B3: ISSA KHOORY VILLA
A4: Engineer : | B4: LOCI CONSULTANT
A5: Contractor : | B5: CONSTECH CONSTRUCTION
A6: PLOT NO: | B6: 6150477-NADD AL SHIBA SECOND
A9: MAIN VILLA
A10: SL NO. | B10: DESCRIPTION | C10: QTY | D10: UNIT | E10: BOQ QTY | F10: Diff
B12: Screed | C12: =PCC!R11 -> 44.067875
A13: 1 | B13: Site Clearance (29M X 38M) | C13: =(29*38)-C31 -> #REF! | D13: m2 | E13: 700 | F13: =C13-E13 -> #REF! | G13: LESS
A14: 2 | B14: Excavation - Option 1 - Mass Excavation | C14: =EARTHWORKS!O11 -> 1776 | D14: m3 | F14: =C14-E14 -> 1776 | G14: ADDITION
A15: 4 | B15: Back Filling | C15: =C14-SUMMARY!C13-SUMMARY!C15-SUMMARY!C16-SUMMARY!C19 -> -2388.1895 | D15: m3 | F15: =C15-E15 -> -2388.1895
A16: 5 | B16: Disposal | C16: =C14-C15 -> 4164.1895 | D16: m3 | F16: =C16-E16 -> 4164.1895
A17: 6 | B17: Soil Compaction | D17: m2 | F17: =C17-E17 -> 0
A18: 7 | B18: Antitermite - Horz | C18: =PCC!M11 -> 881.3575 | D18: m2 | F18: =C18-E18 -> 881.3575
A19: 8 | B19: Antitermite - Vert | C19: =PCC!N11+#REF! -> #REF! | D19: m2 | F19: =C19-E19 -> #REF!
A20: 9 | B20: Polythene Sheet | C20: =PCC!Q11 -> 881.3575 | D20: m2 | F20: =C20-E20 -> 881.3575
A21: 10 | B21: Road Base one layer 250mm thk | D21: m3 | F21: =C21-E21 -> 0
A23: 11 | B23: SUBSTRUCTURE WATER PROOFING - HORZ | C23: =PCC!O11+#REF! -> #REF!
B24: SUBSTRUCTURE WATER PROOFING - VERT | C24: =PCC!P11+#REF! -> #REF!
A27: MULTI PURPOSE ROOM
A28: SL NO. | B28: DESCRIPTION | C28: QTY | D28: UNIT | E28: BOQ QTY | F28: Diff
A30: 1 | B30: Site Clearance | C30: 265 | D30: m2 | E30: 60
A31: 2 | B31: Excavation - Option 1 - Mass Excavation | C31: =EARTHWORKS!#REF! -> #REF! | D31: m3 | F31: =C31-E31 -> #REF! | G31: ADDITION
A32: 4 | B32: Back Filling | D32: m3 | F32: =C32-E32 -> 0
A33: 5 | B33: Disposal | D33: m3 | F33: =C33-E33 -> 0
A34: 6 | B34: Soil Compaction | D34: m2 | F34: =C34-E34 -> 0
A35: 7 | B35: Antitermite - Horz | C35: =PCC!#REF! -> #REF! | D35: m2 | F35: =C35-E35 -> #REF!
A36: 8 | B36: Antitermite - Vert | C36: =PCC!#REF!+#REF! -> #REF! | D36: m2 | F36: =C36-E36 -> #REF!
A37: 9 | B37: Polythene Sheet | C37: =PCC!#REF! -> #REF! | D37: m2 | F37: =C37-E37 -> #REF!
A38: 10 | B38: Road Base one layer 250mm thk | D38: m3 | F38: =C38-E38 -> 0
B40: SUBSTRUCTURE WATER PROOFING - HORZ | C40: =PCC!#REF!+#REF! -> #REF!
B41: SUBSTRUCTURE WATER PROOFING - VERT | C41: =PCC!#REF!+#REF! -> #REF!

Sheet Level Cal (2)
E3: DMD Level | F3: Design Level | M3: DMD Level | N3: Design Level
D6: Gate Level | E6: =3.55+0.3 -> 3.85 | F6: 0 | G6: As per Setting out Plan Drg Ref, 30cm above road level | M6: =3.55+0.3 -> 3.85 | N6: 0
D8: Asphalt Road | E8: 3.55 | M8: 3.55
D10: OGL | E10: 3.425 | F10: =-(E6-E10) -> -0.425 | G10: As per the survey Report | M10: 2 | N10: =-(M6-M10) -> -1.85
C12: =E10-E12 -> 1.075 | D12: Foundation Level | E12: 2.35 | F12: =-(E6-E12) -> -1.5 | M12: =M10*C12 -> 2.15 | N12: =-(M6-M12) -> -1.7
D14: PCC Level | E14: =E12-0.1 -> 2.25 | F14: =-(E6-E14) -> -1.6 | G14: PCC + Blinding 50mm | M14: =M12-0.1 -> 2.05 | N14: =-(M6-M14) -> -1.8
D16: No Road Base
D18: Water Tank | E18: =E8-3.95 -> -0.4 | F18: =-(E6-E18) -> -4.25 | G18: Water Tank Footing level(-3.95) | M18: =M8-3.95 -> -0.4 | N18: =-(M6-M18) -> -4.25
U19: WATER TANK
U20: As per Sectional Plan
I21: =E10-E12 -> 1.075 | U21: 1.5 | V21: height
I22: =E6-E12 -> 1.5 | U22: 0.5
D23: Water Table | E23: 0.6 | F23: =-(E6-E23) -> -3.25 | M23: 0.6 | N23: =-(M6-M23) -> -3.25 | U23: 1
U24: 0.1
U25: 0.2 | V25: Top Slab
E26: =E12-0.25 -> 2.1 | M26: =M12-0.25 -> 1.9 | U26: 0.5 | V26: Bottom Slab/Raft
U27: =SUM(U21:U26) -> 3.8 | V27: Depth
E28: =E6-3.6 -> 0.25 | M28: =M6-3.6 -> 0.25
U29: As per Structural Plan
U30: -3.1 | V30: SSL
U31: -0.5 | V31: Raft Thickness
U32: =U30+U31 -> -3.6 | V32: Depth
U33: 0.05 | V33: Protection Screed
U34: 0.05 | V34: Blinding
U35: 0.25 | V35: Road Base
U36: =U32+-SUM(U33:U35) -> -3.95 | V36: Total Depth

Sheet EARTHWORKS
A1: Project : | B1: KHANNA VILLA, 3630160-AL MANARA DUBAI
A2: Employer : | B2: TARUN HARISH CHNADRA KHANNA
A3: Engineer : | B3: LOCI CONSULTANT
A4: Contractor : | B4: CONSTECH CONSTRUCTION
A6: EARTHWORKS- MAIN VILLA
A8: SI NO | B8: DRW NO | C8: REV | D8: LOCATION | E8: DESCRIPTION | F8: OGL | G8: Foundation PCC Lvl | H8: NO | I8: LENGTH | K8: WIDTH | M8: DEPTH | N8: AREA | O8: EXCAVATION | P8: LESS 300M3 TO RETAIN | Q8: +30% Shrinkage factor | R8: QUERY | S8: ANSWER
I9: (m) | K9: (m) | M9: (m) | N9: (m²) | O9: (m³)
A11: A | B11: EXCAVATION MAIN VILLA | N11: =MROUND(N15,1) -> 1038 | O11: =MROUND(O15,1) -> 1776
A12: 1 | B12: S-105 | C12: R0 | E12: MASS EXCAVATION- MAIN VILLA | F12: ='Level Cal'!$F$10 -> -0.13 | G12: ='Level Cal'!$F$14 -> -1.6 | H12: 1 | I12: 942.7 | M12: =-(G12-F12) -> 1.47 | N12: =H12*I12 -> 942.7 | O12: =H12*M12*N12 -> 1385.769 | R12: Refer Level Calculation
E13: WATER TANK | F13: ='Level Cal'!F10 -> -0.13 | G13: ='Level Cal'!F18 -> -4.25 | H13: 1 | I13: 94.8 | M13: =-(G13-F13) -> 4.12 | N13: =H13*I13 -> 94.8 | O13: =H13*M13*N13 -> 390.576 | R13: Refer Level Calculation
E15: TOTAL | N15: =SUM(N12:N14) -> 1037.5 | O15: =SUM(O12:O14) -> 1776.345 | P15: =O15-300 -> 1476.345 | Q15: =P15*1.3 -> 1919.2485
A18: A | B18: BACKFILL MAIN VILLA | N18: =MROUND(N25,1) -> 76 | O18: =MROUND(O25,1) -> 1009
A19: 1 | C19: R0 | E19: MASS EXCAVATION- MAIN VILLA | O19: =O12 -> 1385.769
E20: VOLUME OF CONCRETE (FOOTING) | O20: =-SUM('Concrete Substructure'!K14:K27) -> -138.562
E21: VOLUME OF NECK COLUMN | O21: =-SUM('Concrete Substructure'!K45:K57) -> -7.0125
E22: VOLUME OF LIFT PIT | M22: 2 | N22: 5 | O22: =M22*N22*-1 -> -10
E23: WATER TANK | M23: ='Concrete Substructure'!I42 -> 3.1 | N23: ='Concrete Substructure'!J26 -> 71.2 | O23: =M23*N23*-1 -> -220.72 | R23: Refer Level Calculation
E25: TOTAL | N25: =SUM(N19:N24) -> 76.2 | O25: =SUM(O19:O24) -> 1009.4745
E27: DISPOSAL | O27: =O15-O25 -> 766.8705

Sheet PCC
A2: Project : | B2: KHANNA VILLA, 3630160-AL MANARA DUBAI
A3: Employer : | B3: TARUN HARISH CHNADRA KHANNA
A4: Engineer : | B4: LOCI CONSULTANT
A5: Contractor : | B5: CONSTECH CONSTRUCTION
A6: PCC - MAIN VILLA
A8: SI NO | B8: DRW NO | C8: REV | D8: LOCATION | E8: DESCRIPTION | F8: NO | G8: LENGTH | H8: WIDTH | I8: DEPTH | J8: AREA | K8: CONCRETE QTY | L8: SHUTTERING | M8: ANTI TERMITE Horz | N8: ANTI TERMITE Vert | O8: WATER PROOFING HORZ | P8: WATER PROOFING VERT | Q8: POLYTHENE SHEET | R8: 50mm thk Protection Screed | S8: Road Base | T8: QUERY | U8: ANSWER
G9: (m) | H9: (m) | I9: (m) | J9: (m²) | K9: (m³) | L9: (m²) | M9: (m²) | N9: (m²) | O9: (m²) | P9: (m²) | Q9: (m²) | R9: (m³) | S9: (m²)
A11: A. | B11: PCC | K11: =K45 -> 44.067875 | L11: =L45 -> 60.49 | M11: =M45 -> 881.3575 | N11: =N45 -> 60.49 | O11: =O45 -> 881.3575 | P11: =P45 -> 60.49 | Q11: =Q45 -> 881.3575 | R11: =R45 -> 44.067875 | S11: =S45 -> 881.3575
A13: 1 | B13: 269-S-100 | C13: R0 | D13: FOOTING
E14: F1 | F14: 4 | G14: 1.3 | H14: 1.6 | I14: 0.05 | J14: =F14*G14*H14 -> 8.32 | K14: =J14*I14 -> 0.416 | L14: =F14*2*(G14+H14)*I14 -> 1.16 | M14: =J14 -> 8.32 | N14: =L14 -> 1.16 | O14: =J14 -> 8.32 | P14: =L14 -> 1.16 | Q14: =J14 -> 8.32 | R14: =J14*0.05 -> 0.416 | S14: =J14 -> 8.32
E15: F2 | F15: 2 | G15: 1.4 | H15: 1.8 | I15: 0.05 | J15: =F15*G15*H15 -> 5.04 | K15: =J15*I15 -> 0.252 | L15: =F15*2*(G15+H15)*I15 -> 0.64 | M15: =J15 -> 5.04 | N15: =L15 -> 0.64 | O15: =J15 -> 5.04 | P15: =L15 -> 0.64 | Q15: =J15 -> 5.04 | R15: =J15*0.05 -> 0.252 | S15: =J15 -> 5.04
E16: F3 | F16: 2 | G16: 1.5 | H16: 1.8 | I16: 0.05 | J16: =F16*G16*H16 -> 5.4 | K16: =J16*I16 -> 0.27 | L16: =F16*2*(G16+H16)*I16 -> 0.66 | M16: =J16 -> 5.4 | N16: =L16 -> 0.66 | O16: =J16 -> 5.4 | P16: =L16 -> 0.66 | Q16: =J16 -> 5.4 | R16: =J16*0.05 -> 0.27 | S16: =J16 -> 5.4
E17: F4 | F17: 3 | G17: 2 | H17: 2.3 | I17: 0.05 | J17: =F17*G17*H17 -> 13.8 | K17: =J17*I17 -> 0.69 | L17: =F17*2*(G17+H17)*I17 -> 1.29 | M17: =J17 -> 13.8 | N17: =L17 -> 1.29 | O17: =J17 -> 13.8 | P17: =L17 -> 1.29 | Q17: =J17 -> 13.8 | R17: =J17*0.05 -> 0.69 | S17: =J17 -> 13.8
E18: F5 | F18: 4 | G18: 2.1 | H18: 2.5 | I18: 0.05 | J18: =F18*G18*H18 -> 21 | K18: =J18*I18 -> 1.05 | L18: =F18*2*(G18+H18)*I18 -> 1.84 | M18: =J18 -> 21 | N18: =L18 -> 1.84 | O18: =J18 -> 21 | P18: =L18 -> 1.84 | Q18: =J18 -> 21 | R18: =J18*0.05 -> 1.05 | S18: =J18 -> 21
E19: F6 | F19: 4 | G19: 2.3 | H19: 2.9 | I19: 0.05 | J19: =F19*G19*H19 -> 26.68 | K19: =J19*I19 -> 1.334 | L19: =F19*2*(G19+H19)*I19 -> 2.08 | M19: =J19 -> 26.68 | N19: =L19 -> 2.08 | O19: =J19 -> 26.68 | P19: =L19 -> 2.08 | Q19: =J19 -> 26.68 | R19: =J19*0.05 -> 1.334 | S19: =J19 -> 26.68
E20: F7 | F20: 2 | G20: 2.4 | H20: 3.2 | I20: 0.05 | J20: =F20*G20*H20 -> 15.36 | K20: =J20*I20 -> 0.768 | L20: =F20*2*(G20+H20)*I20 -> 1.12 | M20: =J20 -> 15.36 | N20: =L20 -> 1.12 | O20: =J20 -> 15.36 | P20: =L20 -> 1.12 | Q20: =J20 -> 15.36 | R20: =J20*0.05 -> 0.768 | S20: =J20 -> 15.36
E21: CF1 | F21: 1 | G21: 1.5 | H21: 3.2 | I21: 0.05 | J21: =F21*G21*H21 -> 4.8 | K21: =J21*I21 -> 0.24 | L21: =F21*2*(G21+H21)*I21 -> 0.47 | M21: =J21 -> 4.8 | N21: =L21 -> 0.47 | O21: =J21 -> 4.8 | P21: =L21 -> 0.47 | Q21: =J21 -> 4.8 | R21: =J21*0.05 -> 0.24 | S21: =J21 -> 4.8
E22: CF2 | F22: 2 | G22: 2.1 | H22: 4 | I22: 0.05 | J22: =F22*G22*H22 -> 16.8 | K22: =J22*I22 -> 0.84 | L22: =F22*2*(G22+H22)*I22 -> 1.22 | M22: =J22 -> 16.8 | N22: =L22 -> 1.22 | O22: =J22 -> 16.8 | P22: =L22 -> 1.22 | Q22: =J22 -> 16.8 | R22: =J22*0.05 -> 0.84 | S22: =J22 -> 16.8
E23: CF3 Raft 3 | F23: 1 | I23: 0.05 | J23: =15.8*1.1 -> 17.38 | K23: =J23*I23 -> 0.869 | L23: =17.1*I23 -> 0.855 | M23: =J23 -> 17.38 | N23: =L23 -> 0.855 | O23: =J23 -> 17.38 | P23: =L23 -> 0.855 | Q23: =J23 -> 17.38 | R23: =J23*0.05 -> 0.869 | S23: =J23 -> 17.38
E24: FC1 | F24: 37 | G24: 1.1 | H24: 1.3 | I24: 0.05 | J24: =F24*G24*H24 -> 52.91 | K24: =J24*I24 -> 2.6455 | L24: =F24*2*(G24+H24)*I24 -> 8.88 | M24: =J24 -> 52.91 | N24: =L24 -> 8.88 | O24: =J24 -> 52.91 | P24: =L24 -> 8.88 | Q24: =J24 -> 52.91 | R24: =J24*0.05 -> 2.6455 | S24: =J24 -> 52.91
E25: FC2 | F25: 3 | G25: 1.05 | H25: 1.05 | I25: 0.05 | J25: =F25*G25*H25 -> 3.3075 | K25: =J25*I25 -> 0.165375 | L25: =F25*2*(G25+H25)*I25 -> 0.63 | M25: =J25 -> 3.3075 | N25: =L25 -> 0.63 | O25: =J25 -> 3.3075 | P25: =L25 -> 0.63 | Q25: =J25 -> 3.3075 | R25: =J25*0.05 -> 0.165375 | S25: =J25 -> 3.3075
E26: Raft 1 | F26: 1 | I26: 0.05 | J26: =71.2*1.1 -> 78.32 | K26: =J26*I26 -> 3.916 | L26: =44.1*I26 -> 2.205 | M26: =J26 -> 78.32 | N26: =L26 -> 2.205 | O26: =J26 -> 78.32 | P26: =L26 -> 2.205 | Q26: =J26 -> 78.32 | R26: =J26*0.05 -> 3.916 | S26: =J26 -> 78.32
E27: Raft 2 | F27: 1 | I27: 0.05 | J27: =51.9*1.1 -> 57.09 | K27: =J27*I27 -> 2.8545 | L27: =32.2*I27 -> 1.61 | M27: =J27 -> 57.09 | N27: =L27 -> 1.61 | O27: =J27 -> 57.09 | P27: =L27 -> 1.61 | Q27: =J27 -> 57.09 | R27: =J27*0.05 -> 2.8545 | S27: =J27 -> 57.09
A29: 2 | B29: 269-S-100 | C29: R0 | D29: STRAP BEAMS | E29: SB1 | F29: 1 | G29: 8.5 | H29: 0.25 | I29: 0.05 | J29: =F29*G29*H29 -> 2.125 | K29: =J29*I29 -> 0.10625 | L29: =F29*2*(G29+H29)*I29 -> 0.875 | M29: =J29 -> 2.125 | N29: =L29 -> 0.875 | O29: =J29 -> 2.125 | P29: =L29 -> 0.875 | Q29: =J29 -> 2.125 | R29: =J29*0.05 -> 0.10625 | S29: =J29 -> 2.125
A31: 3 | B31: 269-S-101-A | C31: R0 | D31: GROUND BEAMS | E31: GB1 | F31: 1 | G31: 164.4 | H31: 0.25 | I31: 0.05 | J31: =F31*G31*H31 -> 41.1 | K31: =J31*I31 -> 2.055 | L31: =F31*2*(G31+H31)*I31 -> 16.465 | M31: =J31 -> 41.1 | N31: =L31 -> 16.465 | O31: =J31 -> 41.1 | P31: =L31 -> 16.465 | Q31: =J31 -> 41.1 | R31: =J31*0.05 -> 2.055 | S31: =J31 -> 41.1
E32: GB2 | F32: 1 | G32: 18.4 | H32: 0.3 | I32: 0.05 | J32: =F32*G32*H32 -> 5.52 | K32: =J32*I32 -> 0.276 | L32: =F32*2*(G32+H32)*I32 -> 1.87 | M32: =J32 -> 5.52 | N32: =L32 -> 1.87 | O32: =J32 -> 5.52 | P32: =L32 -> 1.87 | Q32: =J32 -> 5.52 | R32: =J32*0.05 -> 0.276 | S32: =J32 -> 5.52
E33: GB3 | F33: 1 | G33: 13.2 | H33: 0.25 | I33: 0.05 | J33: =F33*G33*H33 -> 3.3 | K33: =J33*I33 -> 0.165 | L33: =F33*2*(G33+H33)*I33 -> 1.345 | M33: =J33 -> 3.3 | N33: =L33 -> 1.345 | O33: =J33 -> 3.3 | P33: =L33 -> 1.345 | Q33: =J33 -> 3.3 | R33: =J33*0.05 -> 0.165 | S33: =J33 -> 3.3
E34: GB4 | F34: 1 | G34: 14.9 | H34: 0.3 | I34: 0.05 | J34: =F34*G34*H34 -> 4.47 | K34: =J34*I34 -> 0.2235 | L34: =F34*2*(G34+H34)*I34 -> 1.52 | M34: =J34 -> 4.47 | N34: =L34 -> 1.52 | O34: =J34 -> 4.47 | P34: =L34 -> 1.52 | Q34: =J34 -> 4.47 | R34: =J34*0.05 -> 0.2235 | S34: =J34 -> 4.47
E35: GB5 | F35: 1 | G35: 21.3 | H35: 0.25 | I35: 0.05 | J35: =F35*G35*H35 -> 5.325 | K35: =J35*I35 -> 0.26625 | L35: =F35*2*(G35+H35)*I35 -> 2.155 | M35: =J35 -> 5.325 | N35: =L35 -> 2.155 | O35: =J35 -> 5.325 | P35: =L35 -> 2.155 | Q35: =J35 -> 5.325 | R35: =J35*0.05 -> 0.26625 | S35: =J35 -> 5.325
E36: GB6 | F36: 1 | G36: 3.5 | H36: 0.25 | I36: 0.05 | J36: =F36*G36*H36 -> 0.875 | K36: =J36*I36 -> 0.04375 | L36: =F36*2*(G36+H36)*I36 -> 0.375 | M36: =J36 -> 0.875 | N36: =L36 -> 0.375 | O36: =J36 -> 0.875 | P36: =L36 -> 0.375 | Q36: =J36 -> 0.875 | R36: =J36*0.05 -> 0.04375 | S36: =J36 -> 0.875
E37: GB7 | F37: 1 | G37: 1.5 | H37: 0.25 | I37: 0.05 | J37: =F37*G37*H37 -> 0.375 | K37: =J37*I37 -> 0.01875 | L37: =F37*2*(G37+H37)*I37 -> 0.175 | M37: =J37 -> 0.375 | N37: =L37 -> 0.175 | O37: =J37 -> 0.375 | P37: =L37 -> 0.175 | Q37: =J37 -> 0.375 | R37: =J37*0.05 -> 0.01875 | S37: =J37 -> 0.375
E38: B | F38: 1 | G38: 110.3 | H38: 0.2 | I38: 0.05 | J38: =F38*G38*H38 -> 22.06 | K38: =J38*I38 -> 1.103 | L38: =F38*2*(G38+H38)*I38 -> 11.05 | M38: =J38 -> 22.06 | N38: =L38 -> 11.05 | O38: =J38 -> 22.06 | P38: =L38 -> 11.05 | Q38: =J38 -> 22.06 | R38: =J38*0.05 -> 1.103 | S38: =J38 -> 22.06
A40: 4 | B40: 269-S-101-B | C40: R0 | D40: GRADE SLAB | F40: 1 | G40: 470 | I40: 0.05 | J40: =F40*G40 -> 470 | K40: =J40*I40 -> 23.5 | M40: =J40 -> 470 | N40: =L40 -> 0 | O40: =J40 -> 470 | P40: =L40 -> 0 | Q40: =J40 -> 470 | R40: =J40*0.05 -> 23.5 | S40: =J40 -> 470
A42: 5 | B42: S-504 | C42: R0 | D42: WATER Tank | E42: Included in Raft 1 | J42: =F42*G42 -> 0 | K42: =J42*I42 -> 0 | L42: =F42*140*I42 -> 0
A45: TOTAL | J45: =SUM(J28:J44) -> 555.15 | K45: =SUM(K13:K44) -> 44.067875 | L45: =SUM(L13:L44) -> 60.49 | M45: =SUM(M13:M44) -> 881.3575 | N45: =SUM(N13:N44) -> 60.49 | O45: =SUM(O13:O44) -> 881.3575 | P45: =SUM(P13:P44) -> 60.49 | Q45: =SUM(Q13:Q44) -> 881.3575 | R45: =SUM(R13:R44) -> 44.067875 | S45: =SUM(S13:S44) -> 881.3575
D49: ANTI TERMITE
D50: VERTICAL
D51: Footings | E51: 479.8 | F51: =EARTHWORKS!#REF! -> #REF! | G51: =E51*F51 -> #REF!
D52: Water Tank | E52: 31.6 | F52: =EARTHWORKS!M13 -> 4.12 | G52: =E52*F52 -> 130.192
G53: =SUM(G51:G52) -> #REF!

Sheet Waterproofing Works
A2: Project : | B2: KHANNA VILLA, 3630160-AL MANARA DUBAI
A3: Employer : | B3: TARUN HARISH CHNADRA KHANNA
A4: Engineer : | B4: LOCI CONSULTANT
A5: Contractor : | B5: CONSTECH CONSTRUCTION
A6: WATERPROOFING WORKS
A8: SI NO | B8: DRW NO | C8: REV | D8: LOCATION | E8: DESCRIPTION | F8: NO | G8: LENGTH | H8: WIDTH | I8: DEPTH | J8: AREA | K8: CONCRETE QTY | L8: SHUTTERING | M8: ANTI TERMITE Horz | N8: ANTI TERMITE Vert | O8: WATER PROOFING HORZ | P8: WATER PROOFING VERT | Q8: POLYTHENE SHEET | R8: 50mm thk Protection Screed | S8: QUERY | T8: ANSWER
G9: (m) | H9: (m) | I9: (m) | J9: (m²) | K9: (m³) | L9: (m²) | M9: (m²) | N9: (m²) | O9: (m²) | P9: (m²) | Q9: (m²) | R9: (m³)
A11: A. | B11: PCC | K11: =K124 -> 2.16 | L11: =L124 -> 6.48 | M11: =M124 -> 7.2 | N11: =N124 -> 6.48 | O11: =O124 -> 7.2 | P11: =P124 -> 6.48 | Q11: =Q124 -> 7.2 | R11: =R124 -> 0.36
A13: 1 | B13: WATER TANK | C13: R0 | D13: FOOTING
E14: F1 | F14: 4 | G14: 1.2 | H14: 1.5 | I14: 0.3 | J14: =F14*G14*H14 -> 7.2 | K14: =J14*I14 -> 2.16 | L14: =F14*2*(G14+H14)*I14 -> 6.48 | M14: =J14 -> 7.2 | N14: =L14 -> 6.48 | O14: =J14 -> 7.2 | P14: =L14 -> 6.48 | Q14: =J14 -> 7.2 | R14: =J14*0.05 -> 0.36
B16: WET AREAS | C16: R0 | D16: GROUND FLOOR
A17: 2 | D17: Guest Bathroom | E17: Horizontal | F17: 1 | J17: 6.75
E18: Vertical @ Shower Area | F18: 1 | G18: 6 | I18: 2.25 | J18: =PRODUCT(F18:I18) -> 13.5
E19: Vertical @ WC Area | F19: 1 | G19: 1.68 | I19: 0.6 | J19: =PRODUCT(F19:I19) -> 1.008
E20: Vertical @ Sink Area | F20: 1 | G20: 2.7 | I20: 0.6 | J20: =PRODUCT(F20:I20) -> 1.62
E21: 150mm above FFL | F21: 1 | G21: =0.75+0.3+0.3+0.2 -> 1.55
D23: Maids Bathroom | E23: Horizontal | F23: 1 | J23: 6.2
E24: Vertical @ Shower Area | F24: 1 | G24: 3.58 | I24: 2.25 | J24: =PRODUCT(F24:I24) -> 8.055
E25: Vertical @ WC Area | F25: 1 | G25: 4.1 | I25: 0.6 | J25: =PRODUCT(F25:I25) -> 2.46
E26: Vertical @ Sink Area | F26: 1 | G26: 2.87 | I26: 0.6 | J26: =PRODUCT(F26:I26) -> 1.722
E27: 150mm above FFL | F27: 1 | G27: =1.55+2.21+0.71 -> 4.47
D29: Drivers Bathroom | E29: Horizontal | F29: 1 | J29: 4.7
E30: Vertical @ Shower Area | F30: 1 | G30: 4.24 | I30: 2.25 | J30: =PRODUCT(F30:I30) -> 9.54
E31: Vertical @ WC Area | F31: 1 | G31: 1.86 | I31: 0.6 | J31: =PRODUCT(F31:I31) -> 1.116
E32: Vertical @ Sink Area | F32: 1 | G32: 1.64 | I32: 0.6 | J32: =PRODUCT(F32:I32) -> 0.984
E33: 150mm above FFL | F33: 1 | G33: 0.8
D35: Laundry Area | E35: Horizontal | F35: 1 | J35: 7.615
E36: Vertical @ Shower Area | F36: 1
E37: Vertical @ Machine Area | F37: 1 | I37: 0.6 | J37: =PRODUCT(F37:I37) -> 0.6
E38: Vertical @ Sink Area | F38: 1
E39: 150mm above FFL | F39: 1 | G39: =3.37*2 -> 6.74
D41: Powder Room 01 | E41: Horizontal | F41: 1 | J41: 3.1
E42: Vertical @ Shower Area | F42: 1
E43: Vertical @ WC Area | F43: 1 | G43: 2.76 | I43: 0.6 | J43: =PRODUCT(F43:I43) -> 1.656
E44: Vertical @ Sink Area | F44: 1 | G44: 1.47 | I44: 0.6 | J44: =PRODUCT(F44:I44) -> 0.882
E45: 150mm above FFL | F45: 1 | G45: =0.53+2.05 -> 2.58
D47: Powder Room 02 | E47: Horizontal | F47: 1 | J47: 3.1
E48: Vertical @ Shower Area | F48: 1
E49: Vertical @ WC Area | F49: 1 | G49: 2.76 | I49: 0.6 | J49: =PRODUCT(F49:I49) -> 1.656
E50: Vertical @ Sink Area | F50: 1 | G50: 1.47 | I50: 0.6 | J50: =PRODUCT(F50:I50) -> 0.882
...

Sheet Concrete Substructure
A2: Project : | B2: KHANNA VILLA, 3630160-AL MANARA DUBAI
A3: Employer : | B3: TARUN HARISH CHNADRA KHANNA
A4: Engineer : | B4: LOCI CONSULTANT
A5: Contractor : | B5: CONSTECH CONSTRUCTION
A6: SUBSTRUCTURE CONCRETE
A8: SI NO | B8: DRW NO | C8: REV | D8: LOCATION | E8: DESCRIPTION | F8: NO | G8: LENGTH | H8: WIDTH | I8: DEPTH | J8: AREA | K8: CONCRETE QTY | L8: SHUTTERING | M8: ANTI TERMITE Horz | N8: ANTI TERMITE Vert | O8: WATER PROOFING HORZ | P8: WATER PROOFING VERT | Q8: POLYTHENE SHEET | R8: 50mm thk Protection Screed | S8: QUERY | T8: ANSWER
G9: (m) | H9: (m) | I9: (m) | J9: (m²) | K9: (m³) | L9: (m²) | M9: (m²) | N9: (m²) | O9: (m²) | P9: (m²) | Q9: (m²) | R9: (m³)
A11: A. | B11: PCC | K11: =K66 -> 301.49065 | L11: =L66 -> 1015.584 | M11: =M66 -> 924.67 | N11: =N66 -> 553.584 | O11: =O66 -> 924.67 | P11: =P66 -> 680.154 | Q11: =Q66 -> 924.67 | R11: =R66 -> 46.2335
A13: 1 | B13: 269-S-100 | C13: R0 | D13: FOOTING
E14: F1 | F14: 4 | G14: 1.2 | H14: 1.5 | I14: 0.3 | J14: =F14*G14*H14 -> 7.2 | K14: =J14*I14 -> 2.16 | L14: =F14*2*(G14+H14)*I14 -> 6.48 | M14: =J14 -> 7.2 | N14: =L14 -> 6.48 | O14: =J14 -> 7.2 | P14: =L14 -> 6.48 | Q14: =J14 -> 7.2 | R14: =J14*0.05 -> 0.36
E15: F2 | F15: 2 | G15: 1.3 | H15: 1.7 | I15: 0.3 | J15: =F15*G15*H15 -> 4.42 | K15: =J15*I15 -> 1.326 | L15: =F15*2*(G15+H15)*I15 -> 3.6 | M15: =J15 -> 4.42 | N15: =L15 -> 3.6 | O15: =J15 -> 4.42 | P15: =L15 -> 3.6 | Q15: =J15 -> 4.42 | R15: =J15*0.05 -> 0.221
E16: F3 | F16: 2 | G16: 1.4 | H16: 1.7 | I16: 0.3 | J16: =F16*G16*H16 -> 4.76 | K16: =J16*I16 -> 1.428 | L16: =F16*2*(G16+H16)*I16 -> 3.72 | M16: =J16 -> 4.76 | N16: =L16 -> 3.72 | O16: =J16 -> 4.76 | P16: =L16 -> 3.72 | Q16: =J16 -> 4.76 | R16: =J16*0.05 -> 0.238
E17: F4 | F17: 3 | G17: 1.9 | H17: 2.2 | I17: 0.4 | J17: =F17*G17*H17 -> 12.54 | K17: =J17*I17 -> 5.016 | L17: =F17*2*(G17+H17)*I17 -> 9.84 | M17: =J17 -> 12.54 | N17: =L17 -> 9.84 | O17: =J17 -> 12.54 | P17: =L17 -> 9.84 | Q17: =J17 -> 12.54 | R17: =J17*0.05 -> 0.627
E18: F5 | F18: 4 | G18: 2 | H18: 2.4 | I18: 0.4 | J18: =F18*G18*H18 -> 19.2 | K18: =J18*I18 -> 7.68 | L18: =F18*2*(G18+H18)*I18 -> 14.08 | M18: =J18 -> 19.2 | N18: =L18 -> 14.08 | O18: =J18 -> 19.2 | P18: =L18 -> 14.08 | Q18: =J18 -> 19.2 | R18: =J18*0.05 -> 0.96
E19: F6 | F19: 4 | G19: 2.2 | H19: 2.8 | I19: 0.4 | J19: =F19*G19*H19 -> 24.64 | K19: =J19*I19 -> 9.856 | L19: =F19*2*(G19+H19)*I19 -> 16 | M19: =J19 -> 24.64 | N19: =L19 -> 16 | O19: =J19 -> 24.64 | P19: =L19 -> 16 | Q19: =J19 -> 24.64 | R19: =J19*0.05 -> 1.232
E20: F7 | F20: 4 | G20: 2.3 | H20: 3.1 | I20: 0.5 | J20: =F20*G20*H20 -> 28.52 | K20: =J20*I20 -> 14.26 | L20: =F20*2*(G20+H20)*I20 -> 21.6 | M20: =J20 -> 28.52 | N20: =L20 -> 21.6 | O20: =J20 -> 28.52 | P20: =L20 -> 21.6 | Q20: =J20 -> 28.52 | R20: =J20*0.05 -> 1.426
E21: CF1 | F21: 1 | G21: 1.4 | H21: 3.1 | I21: 0.4 | J21: =F21*G21*H21 -> 4.34 | K21: =J21*I21 -> 1.736 | L21: =F21*2*(G21+H21)*I21 -> 3.6 | M21: =J21 -> 4.34 | N21: =L21 -> 3.6 | O21: =J21 -> 4.34 | P21: =L21 -> 3.6 | Q21: =J21 -> 4.34 | R21: =J21*0.05 -> 0.217
E22: CF2 | F22: 2 | G22: 2 | H22: 3.9 | I22: 0.4 | J22: =F22*G22*H22 -> 15.6 | K22: =J22*I22 -> 6.24 | L22: =F22*2*(G22+H22)*I22 -> 9.44 | M22: =J22 -> 15.6 | N22: =L22 -> 9.44 | O22: =J22 -> 15.6 | P22: =L22 -> 9.44 | Q22: =J22 -> 15.6 | R22: =J22*0.05 -> 0.78
E23: CF3 Raft 3 | F23: 1 | I23: 0.5 | J23: 15.8 | K23: =J23*I23 -> 7.9 | L23: =17.1*I23 -> 8.55 | M23: =J23 -> 15.8 | N23: =L23 -> 8.55 | O23: =J23 -> 15.8 | P23: =L23 -> 8.55 | Q23: =J23 -> 15.8 | R23: =J23*0.05 -> 0.79
E24: FC1 | F24: 37 | G24: 1 | H24: 1.2 | I24: 0.3 | J24: =F24*G24*H24 -> 44.4 | K24: =J24*I24 -> 13.32 | L24: =F24*2*(G24+H24)*I24 -> 48.84 | M24: =J24 -> 44.4 | N24: =L24 -> 48.84 | O24: =J24 -> 44.4 | P24: =L24 -> 48.84 | Q24: =J24 -> 44.4 | R24: =J24*0.05 -> 2.22
E25: FC2 | F25: 3 | G25: 1 | H25: 1 | I25: 0.3 | J25: =F25*G25*H25 -> 3 | K25: =J25*I25 -> 0.9 | L25: =F25*2*(G25+H25)*I25 -> 3.6 | M25: =J25 -> 3 | N25: =L25 -> 3.6 | O25: =J25 -> 3 | P25: =L25 -> 3.6 | Q25: =J25 -> 3 | R25: =J25*0.05 -> 0.15
E26: Raft 1 | F26: 1 | I26: 0.5 | J26: 71.2 | K26: =J26*I26 -> 35.6 | L26: =44.1*I26 -> 22.05 | M26: =J26 -> 71.2 | N26: =L26 -> 22.05 | O26: =J26 -> 71.2 | P26: =L26 -> 22.05 | Q26: =J26 -> 71.2 | R26: =J26*0.05 -> 3.56
E27: Raft 2 | F27: 1 | I27: 0.6 | J27: 51.9 | K27: =J27*I27 -> 31.14 | L27: =32.2*I27 -> 19.32 | M27: =J27 -> 51.9 | N27: =L27 -> 19.32 | O27: =J27 -> 51.9 | P27: =L27 -> 19.32 | Q27: =J27 -> 51.9 | R27: =J27*0.05 -> 2.595
A29: 2 | B29: 269-S-100 | C29: R0 | D29: STRAP BEAMS | E29: SB1 | F29: 1 | G29: 8.5 | H29: 0.25 | I29: 0.4 | J29: =F29*G29*H29 -> 2.125 | K29: =J29*I29 -> 0.85 | L29: =F29*2*(G29+H29)*I29 -> 7 | M29: =J29 -> 2.125 | N29: =L29 -> 7 | O29: =J29 -> 2.125 | P29: =L29 -> 7 | Q29: =J29 -> 2.125 | R29: =J29*0.05 -> 0.10625
A31: 3 | B31: 269-S-101-A | C31: R0 | D31: GROUND BEAMS | E31: GB1 | F31: 1 | G31: 164.4 | H31: 0.25 | I31: 0.4 | J31: =F31*G31*H31 -> 41.1 | K31: =J31*I31 -> 16.44 | L31: =F31*G31*I31*2 -> 131.52 | M31: =J31 -> 41.1 | N31: =L31 -> 131.52 | O31: =J31 -> 41.1 | P31: =L31 -> 131.52 | Q31: =J31 -> 41.1 | R31: =J31*0.05 -> 2.055
E32: GB2 | F32: 1 | G32: 18.4 | H32: 0.3 | I32: 0.82 | J32: =F32*G32*H32 -> 5.52 | K32: =J32*I32 -> 4.5264 | L32: =F32*G32*I32*2 -> 30.176 | M32: =J32 -> 5.52 | N32: =L32 -> 30.176 | O32: =J32 -> 5.52 | P32: =L32 -> 30.176 | Q32: =J32 -> 5.52 | R32: =J32*0.05 -> 0.276
E33: GB3 | F33: 1 | G33: 13.2 | H33: 0.25 | I33: 0.82 | J33: =F33*G33*H33 -> 3.3 | K33: =J33*I33 -> 2.706 | L33: =F33*G33*I33*2 -> 21.648 | M33: =J33 -> 3.3 | N33: =L33 -> 21.648 | O33: =J33 -> 3.3 | P33: =L33 -> 21.648 | Q33: =J33 -> 3.3 | R33: =J33*0.05 -> 0.165
E34: GB4 | F34: 1 | G34: 14.9 | H34: 0.3 | I34: 0.6 | J34: =F34*G34*H34 -> 4.47 | K34: =J34*I34 -> 2.682 | L34: =F34*G34*I34*2 -> 17.88 | M34: =J34 -> 4.47 | N34: =L34 -> 17.88 | O34: =J34 -> 4.47 | P34: =L34 -> 17.88 | Q34: =J34 -> 4.47 | R34: =J34*0.05 -> 0.2235
E35: GB5 | F35: 1 | G35: 21.3 | H35: 0.25 | I35: 0.6 | J35: =F35*G35*H35 -> 5.325 | K35: =J35*I35 -> 3.195 | L35: =F35*G35*I35*2 -> 25.56 | M35: =J35 -> 5.325 | N35: =L35 -> 25.56 | O35: =J35 -> 5.325 | P35: =L35 -> 25.56 | Q35: =J35 -> 5.325 | R35: =J35*0.05 -> 0.26625
E36: GB6 | F36: 1 | G36: 3.5 | H36: 0.25 | I36: 0.82 | J36: =F36*G36*H36 -> 0.875 | K36: =J36*I36 -> 0.7175 | L36: =F36*G36*I36*2 -> 5.74 | M36: =J36 -> 0.875 | N36: =L36 -> 5.74 | O36: =J36 -> 0.875 | P36: =L36 -> 5.74 | Q36: =J36 -> 0.875 | R36: =J36*0.05 -> 0.04375
E37: GB7 | F37: 1 | G37: 1.5 | H37: 0.25 | I37: 0.67 | J37: =F37*G37*H37 -> 0.375 | K37: =J37*I37 -> 0.25125 | L37: =F37*G37*I37*2 -> 2.01 | M37: =J37 -> 0.375 | N37: =L37 -> 2.01 | O37: =J37 -> 0.375 | P37: =L37 -> 2.01 | Q37: =J37 -> 0.375 | R37: =J37*0.05 -> 0.01875
E38: B | F38: 1 | G38: 110.3 | H38: 0.2 | I38: 0.55 | J38: =F38*G38*H38 -> 22.06 | K38: =J38*I38 -> 12.133 | L38: =F38*G38*I38*2 -> 121.33 | M38: =J38 -> 22.06 | N38: =L38 -> 121.33 | O38: =J38 -> 22.06 | P38: =L38 -> 121.33 | Q38: =J38 -> 22.06 | R38: =J38*0.05 -> 1.103
A40: 4 | B40: 269-S-101-B | C40: R0 | D40: GRADE SLAB | F40: 1 | G40: 530 | I40: 0.15 | J40: 532 | K40: =J40*I40 -> 79.8 | M40: =J40 -> 532 | N40: =L40 -> 0 | O40: =J40 -> 532 | P40: =L40 -> 0 | Q40: =J40 -> 532 | R40: =J40*0.05 -> 26.6
A42: 5 | B42: 269-S-101-B | C42: R0 | D42: WATER Tank | E42: Wall | F42: 1 | G42: 38.1 | H42: 0.25 | I42: =SUM('Level Cal'!Y21:Y24) -> 3.1 | J42: =F42*G42 -> 38.1 | K42: =G42*H42*I42 -> 29.5275 | L42: =F42*140*I42 -> 434 | M42: =73.3*I42 -> 227.23
D43: WATER Tank | E43: Ceiling | F43: 1 | I43: 0.2 | J43: 50.5 | K43: =J43*I43 -> 10.1 | L43: =F43*140*I43 -> 28
V44: =80-57 -> 23
A45: 6 | B45: 269-S-101-A / 269-S-201 | C45: R0 | D45: Neck Columns | E45: C1 | F45: 5 | G45: 0.4 | H45: 0.25 | I45: =1.5-AVERAGE($I$14:$I$27) -> 1.1 | J45: =F45*G45*H45 -> 0.5 | K45: =J45*I45 -> 0.55 | L45: =(G45+H45)*2*I45*F45 -> 7.15 | P45: =L45 -> 7.15
E46: C4 | F46: 6 | G46: 0.6 | H46: 0.25 | I46: =1.5-AVERAGE($I$14:$I$27) -> 1.1 | J46: =F46*G46*H46 -> 0.9 | K46: =J46*I46 -> 0.99 | L46: =(G46+H46)*2*I46*F46 -> 11.22 | P46: =L46 -> 11.22
E47: C | F47: 40 | G47: 0.2 | H47: 0.2 | I47: =1.5-AVERAGE($I$14:$I$27) -> 1.1 | J47: =F47*G47*H47 -> 1.6 | K47: =J47*I47 -> 1.76 | L47: =(G47+H47)*2*I47*F47 -> 35.2 | P47: =L47 -> 35.2
E48: C5 | F48: 3 | G48: 0.6 | H48: 0.25 | I48: =1.5-AVERAGE($I$14:$I$27) -> 1.1 | J48: =F48*G48*H48 -> 0.45 | K48: =J48*I48 -> 0.495 | L48: =(G48+H48)*2*I48*F48 -> 5.61 | P48: =L48 -> 5.61
...

Sheet Concrete SuperStructure
A2: Project : | B2: KHANNA VILLA, 3630160-AL MANARA DUBAI
A3: Employer : | B3: TARUN HARISH CHNADRA KHANNA
A4: Engineer : | B4: LOCI CONSULTANT
A5: Contractor : | B5: CONSTECH CONSTRUCTION
A6: SUPERSTRUCTURE CONCRETE
A8: SI NO | B8: DRW NO | C8: REV | D8: LOCATION | E8: DESCRIPTION | F8: NO | G8: LENGTH | H8: WIDTH | I8: DEPTH | J8: AREA | K8: CONCRETE QTY | L8: SHUTTERING | M8: ANTI TERMITE Horz | N8: ANTI TERMITE Vert | O8: WATER PROOFING HORZ | P8: WATER PROOFING VERT | Q8: POLYTHENE SHEET | R8: 50mm thk Protection Screed | S8: QUERY | T8: ANSWER
G9: (m) | H9: (m) | I9: (m) | J9: (m²) | K9: (m³) | L9: (m²) | M9: (m²) | N9: (m²) | O9: (m²) | P9: (m²) | Q9: (m²) | R9: (m³)
A11: A. | B11: COLUMNS
A13: 1 | B13: 269-S-101-A / 269-S-201 | C13: R0 | D13: Columns (GF TO FF) | E13: C1 | F13: 5 | G13: 0.4 | H13: 0.25 | I13: 4.5 | J13: =F13*G13*H13 -> 0.5 | K13: =F13*G13*H13*I13 -> 2.25 | L13: =(G13+H13)*2*I13*F13 -> 29.25
E14: C4 | F14: 6 | G14: 0.6 | H14: 0.25 | I14: 4.5 | J14: =F14*G14*H14 -> 0.9 | K14: =F14*G14*H14*I14 -> 4.05 | L14: =(G14+H14)*2*I14*F14 -> 45.9
E15: C | F15: 40 | G15: 0.2 | H15: 0.2 | I15: 1.9 | J15: =F15*G15*H15 -> 1.6 | K15: =F15*G15*H15*I15 -> 3.04 | L15: =(G15+H15)*2*I15*F15 -> 60.8
E16: C5 | F16: 3 | G16: 0.6 | H16: 0.25 | I16: 4.5 | J16: =F16*G16*H16 -> 0.45 | K16: =F16*G16*H16*I16 -> 2.025 | L16: =(G16+H16)*2*I16*F16 -> 22.95
E17: C4* | F17: 8 | G17: 0.6 | H17: 0.25 | I17: 4.5 | J17: =F17*G17*H17 -> 1.2 | K17: =F17*G17*H17*I17 -> 5.4 | L17: =(G17+H17)*2*I17*F17 -> 61.2
E18: C4** | F18: 2 | G18: 0.6 | H18: 0.25 | I18: 4.5 | J18: =F18*G18*H18 -> 0.3 | K18: =F18*G18*H18*I18 -> 1.35 | L18: =(G18+H18)*2*I18*F18 -> 15.3
E19: C12 | F19: 2 | G19: 0.25 | H19: 0.25 | I19: 4.5 | J19: =F19*G19*H19 -> 0.125 | K19: =F19*G19*H19*I19 -> 0.5625 | L19: =(G19+H19)*2*I19*F19 -> 9
E20: C11 | F20: 2 | G20: 0.6 | H20: 0.25 | I20: 4.5 | J20: =F20*G20*H20 -> 0.3 | K20: =F20*G20*H20*I20 -> 1.35 | L20: =(G20+H20)*2*I20*F20 -> 15.3
E21: C6* | F21: 1 | G21: 1 | H21: 0.25 | I21: 4.5 | J21: =F21*G21*H21 -> 0.25 | K21: =F21*G21*H21*I21 -> 1.125 | L21: =(G21+H21)*2*I21*F21 -> 11.25
E22: C6 | F22: 1 | G22: 1 | H22: 0.25 | I22: 4.5 | J22: =F22*G22*H22 -> 0.25 | K22: =F22*G22*H22*I22 -> 1.125 | L22: =(G22+H22)*2*I22*F22 -> 11.25
E23: C2 | F23: 1 | G23: 0.8 | H23: 0.25 | I23: 4.5 | J23: =F23*G23*H23 -> 0.2 | K23: =F23*G23*H23*I23 -> 0.9 | L23: =(G23+H23)*2*I23*F23 -> 9.45
E24: C3 | F24: 1 | G24: 0.8 | H24: 0.25 | I24: 4.5 | J24: =F24*G24*H24 -> 0.2 | K24: =F24*G24*H24*I24 -> 0.9 | L24: =(G24+H24)*2*I24*F24 -> 9.45
E25: C1* | F25: 1 | G25: 0.4 | H25: 0.25 | I25: 4.5 | J25: =F25*G25*H25 -> 0.1 | K25: =F25*G25*H25*I25 -> 0.45 | L25: =(G25+H25)*2*I25*F25 -> 5.85
E26: Decorative Column | I26: 4.5 | J26: 1.4 | K26: =+I26*J26 -> 6.3 | L26: =12.4*I26 -> 55.8
B28: 269-S-102-A / 269-S-201 | C28: R0 | D28: Columns (FF TO RF) | E28: C1 | G28: 0.4 | H28: 0.25 | I28: =8.6-4.5 -> 4.1 | J28: =F28*G28*H28 -> 0 | K28: =F28*G28*H28*I28 -> 0 | L28: =(G28+H28)*2*I28*F28 -> 0
E29: C4 | G29: 0.6 | H29: 0.25 | I29: =8.6-4.5 -> 4.1 | J29: =F29*G29*H29 -> 0 | K29: =F29*G29*H29*I29 -> 0 | L29: =(G29+H29)*2*I29*F29 -> 0
E30: C | G30: 0.2 | H30: 0.2 | I30: =8.6-4.5 -> 4.1 | J30: =F30*G30*H30 -> 0 | K30: =F30*G30*H30*I30 -> 0 | L30: =(G30+H30)*2*I30*F30 -> 0
E31: C5 | F31: 2 | G31: 0.6 | H31: 0.25 | I31: =8.6-4.5 -> 4.1 | J31: =F31*G31*H31 -> 0.3 | K31: =F31*G31*H31*I31 -> 1.23 | L31: =(G31+H31)*2*I31*F31 -> 13.94
E32: C4* | F32: 8 | G32: 0.6 | H32: 0.25 | I32: =8.6-4.5 -> 4.1 | J32: =F32*G32*H32 -> 1.2 | K32: =F32*G32*H32*I32 -> 4.92 | L32: =(G32+H32)*2*I32*F32 -> 55.76
E33: C4** | F33: 2 | G33: 0.6 | H33: 0.25 | I33: =8.6-4.5 -> 4.1 | J33: =F33*G33*H33 -> 0.3 | K33: =F33*G33*H33*I33 -> 1.23 | L33: =(G33+H33)*2*I33*F33 -> 13.94
E34: C12 | F34: 2 | G34: 0.25 | H34: 0.25 | I34: =8.6-4.5 -> 4.1 | J34: =F34*G34*H34 -> 0.125 | K34: =F34*G34*H34*I34 -> 0.5125 | L34: =(G34+H34)*2*I34*F34 -> 8.2
E35: C11 | F35: 2 | G35: 0.6 | H35: 0.25 | I35: =8.6-4.5 -> 4.1 | J35: =F35*G35*H35 -> 0.3 | K35: =F35*G35*H35*I35 -> 1.23 | L35: =(G35+H35)*2*I35*F35 -> 13.94
E36: C6* | F36: 1 | G36: 1 | H36: 0.25 | I36: =8.6-4.5 -> 4.1 | J36: =F36*G36*H36 -> 0.25 | K36: =F36*G36*H36*I36 -> 1.025 | L36: =(G36+H36)*2*I36*F36 -> 10.25
E37: C7 | F37: 2 | G37: 0.6 | H37: 0.25 | I37: =8.6-4.5 -> 4.1 | J37: =F37*G37*H37 -> 0.3 | K37: =F37*G37*H37*I37 -> 1.23 | L37: =(G37+H37)*2*I37*F37 -> 13.94
E38: C2 | G38: 0.8 | H38: 0.25 | I38: =8.6-4.5 -> 4.1 | J38: =F38*G38*H38 -> 0 | K38: =F38*G38*H38*I38 -> 0 | L38: =(G38+H38)*2*I38*F38 -> 0
E39: C3 | F39: 1 | G39: 0.8 | H39: 0.25 | I39: =8.6-4.5 -> 4.1 | J39: =F39*G39*H39 -> 0.2 | K39: =F39*G39*H39*I39 -> 0.82 | L39: =(G39+H39)*2*I39*F39 -> 8.61
E40: C1* | F40: 1 | G40: 0.4 | H40: 0.25 | I40: =8.6-4.5 -> 4.1 | J40: =F40*G40*H40 -> 0.1 | K40: =F40*G40*H40*I40 -> 0.41 | L40: =(G40+H40)*2*I40*F40 -> 5.33
E41: Decorative Column | I41: 4.1 | J41: 1.4 | K41: =+I41*J41 -> 5.74 | L41: =12.2*I41 -> 50.02
B43: 269-S-103-A / 269-S-201 | C43: R0 | D43: Columns (RF TO URF) | E43: C8 | F43: 1 | G43: 0.8 | H43: 0.25 | I43: =12.37-8.6 -> 3.77 | J43: =F43*G43*H43 -> 0.2 | K43: =F43*G43*H43*I43 -> 0.754 | L43: =(G43+H43)*2*I43*F43 -> 7.917
E44: C9 | F44: 3 | G44: 0.6 | H44: 0.25 | I44: =12.37-8.6 -> 3.77 | J44: =F44*G44*H44 -> 0.45 | K44: =F44*G44*H44*I44 -> 1.6965 | L44: =(G44+H44)*2*I44*F44 -> 19.227
E45: C10 | F45: 1 | I45: =12.37-8.6 -> 3.77 | J45: =PI()*0.25^2*0.205 -> 0.040251656 | K45: =I45*J45 -> 0.15174874 | L45: =(G45+H45)*2*I45*F45 -> 0
E46: C4** | F46: 2 | G46: 0.6 | H46: 0.25 | I46: =12.37-8.6 -> 3.77 | J46: =F46*G46*H46 -> 0.3 | K46: =F46*G46*H46*I46 -> 1.131 | L46: =(G46+H46)*2*I46*F46 -> 12.818
...

Sheet SUMMARY
A2: Project : | B2: KHANNA VILLA, 3630160-AL MANARA DUBAI
A3: Employer : | B3: TARUN HARISH CHNADRA KHANNA
A4: Engineer : | B4: LOCI CONSULTANT
A5: Contractor : | B5: CONSTECH CONSTRUCTION
A9: SL NO. | B9: DESCRIPTION | C9: CONSTECH | D9: BOQ | E9: VARIANCE | F9: UNIT
B11: SITEWORKS
A13: 1 | B13: Site Clearance | C13: 1392 | D13: 1394 | E13: =C13-D13 -> -2 | F13: m2
A14: 2 | B14: Excavation | C14: =EARTHWORKS!O15 -> 1776.345 | D14: 830 | E14: =C14-D14 -> 946.345 | F14: m3
A15: 3 | B15: Backfilling | C15: =EARTHWORKS!O25 -> 1009.4745 | D15: 310 | E15: =C15-D15 -> 699.4745 | F15: m3
A16: 4 | B16: Road Base | C16: =PCC!S11 -> 881.3575 | D16: 862 | E16: =C16-D16 -> 19.3575 | F16: m3
A17: 5 | B17: Disposal | C17: =C14-C15 -> 766.8705 | D17: 519 | E17: =C17-D17 -> 247.8705 | F17: m3
A18: 6 | B18: Dewatering | D18: 1 | E18: =C18-D18 -> -1 | F18: LS
A19: 7 | B19: Anti-Termite Treatment Horizontal Surfaces | C19: =PCC!M11 -> 881.3575 | D19: 921 | E19: =C19-D19 -> -39.6425 | F19: m2
A20: 8 | B20: Anti-Termite Treatment Vertical Surfaces | C20: =PCC!N11+'Concrete Substructure'!N11 -> 614.074 | D20: 982 | E20: =C20-D20 -> -367.926 | F20: m2
B22: CONCRETE WORK
B23: SUBSTRUCTURE
B24: Plain Concrete
B25: 50mm thick blinding | C25: =PCC!K11 -> 44.067875 | D25: 46
B27: Reinforced Concrete
B28: Raft | C28: ='Concrete Substructure'!K26+'Concrete Substructure'!K27 -> 66.74 | D28: 65
B29: Footing | C29: =SUM('Concrete Substructure'!K14:K25) -> 71.822 | D29: 67 | E29: =C29-D29 -> 4.822
B30: Column Neck | C30: =ROUNDUP(SUM('Concrete Substructure'!K45:K57),0) -> 8 | D30: 9
B31: Wall | C31: =ROUNDUP(SUM('Concrete Substructure'!K60:K62),0) -> 3 | D31: 3
B32: Grade Beam | C32: =ROUNDUP(SUM('Concrete Substructure'!K29:K38),0) -> 44 | D32: 43
B33: Tank Wall | C33: ='Concrete Substructure'!K42 -> 29.5275 | D33: 29
B34: Lift Pit Wall | C34: =ROUND('Concrete Substructure'!K59,0) -> 3 | D34: 3
B35: Slab on grade | C35: =ROUNDUP('Concrete Substructure'!K40,0) -> 80 | D35: 57
B37: Reinforcement
B38: Raft | C38: ='Rebar-Substructure'!F89 -> 5856.5957 | D38: 5608 | E38: =C38-D38 -> 248.59569
B39: Footing | C39: ='Rebar-Substructure'!F88 -> 4690.4007 | D39: 5879 | E39: =C39-D39 -> -1188.5993
B40: Column Neck | C40: ='Rebar-Substructure'!AC62 -> 1884.4987 | D40: 1626 | E40: =C40-D40 -> 258.49875
B41: Wall | C41: ='Rebar-Substructure'!AX30 -> 468.79267 | D41: 508 | E41: =C41-D41 -> -39.207332
B42: Grade Beam | C42: ='Rebar-Substructure'!BR55 -> 7495.6543 | D42: 8109 | E42: =C42-D42 -> -613.34569
B43: Tank Wall | C43: ='Rebar-Substructure'!CM12 -> 3160.0058 | D43: 3115 | E43: =C43-D43 -> 45.005843
B44: Lift Pit Wall | C44: ='Rebar-Substructure'!DH19 -> 958.92996 | D44: 676 | E44: =C44-D44 -> 282.92996
B45: Slab on grade | C45: ='Rebar-Substructure'!EB19 -> 3493.335 | D45: 3076 | E45: =C45-D45 -> 417.33496
B47: Shuttering
B48: To sides of raft | C48: =SUM('Concrete Substructure'!L26:L27) -> 41.37 | D48: 41
B49: To sides of footing | C49: =SUM('Concrete Substructure'!L14:L25) -> 149.35 | D49: 143
B50: To sides of column neck | C50: =SUM('Concrete Substructure'!L45:L57) -> 95.37 | D50: 122
...

Sheet Rebar-Substructure
BO2: GRADE BEAMS | CJ2: TANK WALL | DE2: LIFT PIT WALL | DY2: SLAB ON GRADE
B3: FOOTING | Y3: COLUMN NECK | AT3: SHEAR WALL
AD4: Depth Of Excavation | BO4: Rebars | CJ4: Rebars | DE4: Rebars | DY4: Rebars | DZ4: A = 470
B5: Rebars | Y5: Rebars | AT5: Rebars | BO5: Mark | BP5: Member | BQ5: Bar Name | BR5: Bar | BS5: Spacing | BT5: Depth | BU5: Width | BV5: Length | BW5: Qty | BX5: Timesing | BY5: a | BZ5: b | CA5: c | CB5: d | CC5: e | CD5: Length per Bar | CE5: Total Length | CF5: wt/m | CG5: Total Weight | CJ5: Mark | CK5: Member | CL5: Bar Name | CM5: Bar | CN5: Spacing | CO5: Height | CP5: Width | CQ5: Length | CR5: Qty | CS5: Timesing | CT5: a | CU5: b | CV5: c | CW5: d | CX5: e | CY5: Length per Bar | CZ5: Total Length | DA5: wt/m | DB5: Total Weight | DE5: Mark | DF5: Member | DG5: Bar Name | DH5: Bar | DI5: Spacing | DJ5: Height | DK5: Width | DL5: Length | DM5: Qty | DN5: Timesing | DO5: a | DP5: b | DQ5: c | DR5: d | DS5: e | DT5: Length per Bar | DU5: Total Length | DV5: wt/m | DW5: Total Weight | DY5: Mark | DZ5: Member | EA5: Bar Name | EB5: Bar | EC5: Spacing | ED5: Height | EE5: Width | EF5: Length | EG5: Qty | EH5: Timesing | EI5: a | EJ5: b | EK5: c | EL5: d | EM5: e | EN5: Length per Bar | EO5: Total Length | EP5: wt/m | EQ5: Total Weight
B6: Mark | C6: Member | D6: Bar Name | E6: Bar | F6: Spacing | G6: Length | H6: Width | I6: Thk | J6: Qty | K6: Timesing | L6: a | M6: b | N6: c | O6: d | P6: e | Q6: Length per Bar | R6: Total Length | S6: wt/m | T6: Total Weight | Y6: Mark | Z6: Member | AA6: Bar Name | AB6: Bar | AC6: Spacing | AD6: Length | AE6: Width | AF6: Height | AG6: Qty | AH6: Timesing | AI6: a | AJ6: b | AK6: c | AL6: d | AM6: e | AN6: Length per Bar | AO6: Total Length | AP6: wt/m | AQ6: Total Weight | AT6: Mark | AU6: Member | AV6: Bar Name | AW6: Bar | AX6: Spacing | AY6: Length | AZ6: Width | BA6: Height | BB6: Qty | BC6: Timesing | BD6: a | BE6: b | BF6: c | BG6: d | BH6: e | BI6: Length per Bar | BJ6: Total Length | BK6: wt/m | BL6: Total Weight | BO6: GB-1 | BP6: Grade Beam | BQ6: Bottom Bars | BR6: 16 | BS6: 0 | BT6: 0.4 | BU6: 0.25 | BV6: 4.9 | BW6: 4 | BX6: 1 | BY6: =BV6 -> 4.9 | CD6: =SUM(BY6:CC6) -> 4.9 | CE6: =BW6*CD6*BX6 -> 19.6 | CF6: =PI()*(BR6/1000)^2*0.25*1*7850 -> 1.5783361 | CG6: =CE6*CF6 -> 30.935389 | CL6: Horizontal | CM6: 10 | CN6: 150 | CO6: =1.5+0.5+1+0.1 -> 3.1 | CQ6: 37.2 | CR6: =ROUND((CO6/(CN6/1000))+1,0) -> 22 | CS6: 2 | CT6: =CQ6 -> 37.2 | CY6: =SUM(CT6:CX6) -> 37.2 | CZ6: =CR6*CY6*CS6 -> 1636.8 | DA6: =PI()*(CM6/1000)^2*0.25*1*7850 -> 0.61653756 | DB6: =CZ6*DA6 -> 1009.1487 | DF6: ok | DG6: Vertical | DH6: 20 | DI6: 150 | DJ6: 1.2 | DK6: 0.25 | DL6: 2.35 | DM6: 20 | DN6: 2 | DO6: =DJ6 -> 1.2 | DP6: 0.35 | DQ6: =0.6-0.075 -> 0.525 | DT6: =SUM(DO6:DS6) -> 2.075 | DU6: =DM6*DT6*DN6 -> 83 | DV6: =PI()*(DH6/1000)^2*0.25*1*7850 -> 2.4661502 | DW6: =DU6*DV6 -> 204.69047 | DZ6: ok | EA6: At Long Side | EB6: 10 | EC6: 200 | EE6: 5.3 | EF6: 6.5 | EG6: =ROUND((EE6/(EC6/1000))+1,0) -> 28 | EH6: 1 | EI6: 0.1 | EJ6: =EF7 -> 6.5 | EN6: =SUM(EI6:EM6) -> 6.6 | EO6: =EG6*EN6*EH6 -> 184.8 | EP6: =PI()*(EB6/1000)^2*0.25*1*7850 -> 0.61653756 | EQ6: =EO6*EP6 -> 113.93614
B7: F-01 | C7: Isolated Footing | D7: At Short Span (Bottom) | E7: 12 | F7: 200 | G7: 1.2 | H7: 1.5 | I7: 0.3 | J7: =ROUND(((G7-0.075*2)/(F7/1000))+1,0) -> 6 | K7: 1 | L7: =I7-0.075*2 -> 0.15 | M7: =H7-0.075*2 -> 1.35 | N7: =L7 -> 0.15 | Q7: =SUM(L7:P7) -> 1.65 | R7: =J7*Q7*K7 -> 9.9 | S7: =PI()*(E7/1000)^2*0.25*1*7850 -> 0.88781408 | T7: =R7*S7 -> 8.7893594 | U7: ok | Y7: C1 | Z7: Neck Column | AA7: Vertical Bars | AB7: 16 | AC7: as shown | AD7: 0.4 | AE7: 0.25 | AF7: 1.5 | AG7: 6 | AH7: 1 | AI7: =AF7-0.075 -> 1.425 | AJ7: =16*(AB7/1000) -> 0.256 | AN7: =SUM(AI7:AM7) -> 1.681 | AO7: =AG7*AN7*AH7 -> 10.086 | AP7: =PI()*(AB7/1000)^2*0.25*1*7850 -> 1.5783361 | AQ7: =AO7*AP7 -> 15.919098 | AT7: W1 | AU7: Shear Wall | AV7: Main Vertical Bars | AW7: 20 | AX7: as shown | BA7: 1.5 | BB7: 12 | BC7: 2 | BD7: =BA7-0.075*2 -> 1.35 | BE7: =16*(AW7/1000) -> 0.32 | BI7: =SUM(BD7:BH7) -> 1.67 | BJ7: =BB7*BI7*BC7 -> 40.08 | BK7: =PI()*(AW7/1000)^2*0.25*1*7850 -> 2.4661502 | BL7: =BJ7*BK7 -> 98.843301 | BQ7: Top Bars | BR7: 16 | BS7: 0 | BT7: 0.4 | BU7: 0.25 | BV7: 4.9 | BW7: 6 | BX7: 1 | BY7: =BV7 -> 4.9 | CD7: =SUM(BY7:CC7) -> 4.9 | CE7: =BW7*CD7*BX7 -> 29.4 | CF7: =PI()*(BR7/1000)^2*0.25*1*7850 -> 1.5783361 | CG7: =CE7*CF7 -> 46.403083 | CL7: Vertical | CM7: 12 | CN7: 150 | CO7: =CO6 -> 3.1 | CQ7: 37.2 | CR7: =ROUND((CQ7/(CN7/1000))+1,0) -> 249 | CS7: 2 | CT7: =CO7 -> 3.1 | CU7: =0.5-0.075 -> 0.425 | CV7: 0.4 | CW7: 0.14 | CX7: =0.2-0.05 -> 0.15 | CY7: =SUM(CT7:CX7) -> 4.215 | CZ7: =CR7*CY7*CS7 -> 2099.07 | DA7: =PI()*(CM7/1000)^2*0.25*1*7850 -> 0.88781408 | DB7: =CZ7*DA7 -> 1863.5839 | DG7: Vertical | DH7: 20 | DI7: 150 | DJ7: 1.2 | DL7: 37.2 | DM7: 24 | DN7: 2 | DO7: =DJ7 -> 1.2 | DP7: =DP6 -> 0.35 | DQ7: =DQ6 -> 0.525 | DT7: =SUM(DO7:DS7) -> 2.075 | DU7: =DM7*DT7*DN7 -> 99.6 | DV7: =PI()*(DH7/1000)^2*0.25*1*7850 -> 2.4661502 | DW7: =DU7*DV7 -> 245.62856 | EA7: At Short Side | EB7: 10 | EC7: 200 | EE7: 5.3 | EF7: 6.5 | EG7: =ROUND((EF7/(EC7/1000))+1,0) -> 34 | EH7: 1 | EI7: 0.1 | EJ7: =EE6 -> 5.3 | EN7: =SUM(EI7:EM7) -> 5.4 | EO7: =EG7*EN7*EH7 -> 183.6 | EP7: =PI()*(EB7/1000)^2*0.25*1*7850 -> 0.61653756 | EQ7: =EO7*EP7 -> 113.1963
D8: At Long Span (Bottom) | E8: 12 | F8: 200 | G8: 1.2 | H8: 1.5 | I8: 0.3 | J8: =ROUND(((H8-0.075*2)/(F8/1000))+1,0) -> 8 | K8: 1 | L8: =I8-0.075*2 -> 0.15 | M8: =G8-0.075*2 -> 1.05 | N8: =L8 -> 0.15 | Q8: =SUM(L8:P8) -> 1.35 | R8: =J8*Q8*K8 -> 10.8 | S8: =PI()*(E8/1000)^2*0.25*1*7850 -> 0.88781408 | T8: =R8*S8 -> 9.5883921 | AA8: Column Ties | AB8: 10 | AC8: 200 | AD8: 0.4 | AE8: 0.25 | AF8: 1.5 | AG8: =ROUND(((1.5-0.075)/(AC8/1000))+1,0) -> 8 | AH8: 1 | AI8: =AD8-0.04*2 -> 0.32 | AJ8: =AE8-0.04*2 -> 0.17 | AK8: =AI8 -> 0.32 | AL8: =AJ8 -> 0.17 | AM8: =10*(AB8/1000) -> 0.1 | AN8: =SUM(AI8:AM8) -> 1.08 | AO8: =AG8*AN8*AH8 -> 8.64 | AP8: =PI()*(AB8/1000)^2*0.25*1*7850 -> 0.61653756 | AQ8: =AO8*AP8 -> 5.3268845 | AV8: Intermediate Vertical Bars | AW8: 16 | AX8: 200 | AY8: =2.5-0.55*2 -> 1.4 | BA8: 1.5 | BB8: 14 | BC8: 1 | BD8: =BA8-0.075*2 -> 1.35 | BE8: =16*(AW8/1000) -> 0.256 | BI8: =SUM(BD8:BH8) -> 1.606 | BJ8: =BB8*BI8*BC8 -> 22.484 | BK8: =PI()*(AW8/1000)^2*0.25*1*7850 -> 1.5783361 | BL8: =BJ8*BK8 -> 35.48731 | BQ8: Links | BR8: 10 | BS8: 200 | BT8: 0.4 | BU8: 0.25 | BV8: 4.9 | BW8: =ROUND((BV8/(BS8/1000))+1,0) -> 26 | BX8: 1 | BY8: =BT8-0.04*2 -> 0.32 | BZ8: =BU8-0.04*2 -> 0.17 | CA8: =BY8 -> 0.32 | CB8: =BZ8 -> 0.17 | CC8: =(10*BR8)/1000 -> 0.1 | CD8: =SUM(BY8:CC8) -> 1.08 | CE8: =BW8*CD8*BX8 -> 28.08 | CF8: =PI()*(BR8/1000)^2*0.25*1*7850 -> 0.61653756 | CG8: =CE8*CF8 -> 17.312375 | DG8: Vertical | DH8: 12 | DI8: 200 | DJ8: 1.2 | DL8: 37.2 | DM8: 12 | DN8: 1 | DO8: =DJ8 -> 1.2 | DP8: =DP7 -> 0.35 | DQ8: =DQ7 -> 0.525 | DT8: =SUM(DO8:DS8) -> 2.075 | DU8: =DM8*DT8*DN8 -> 24.9 | DV8: =PI()*(DH8/1000)^2*0.25*1*7850 -> 0.88781408 | DW8: =DU8*DV8 -> 22.106571
D9: At Short Span (Top) | E9: 12 | F9: 250 | G9: 1.2 | H9: 1.5 | I9: 0.3 | J9: =ROUND(((G9-0.075*2)/(F9/1000))+1,0) -> 5 | K9: 1 | L9: =I9-0.075*2 -> 0.15 | M9: =H9-0.075*2 -> 1.35 | N9: =L9 -> 0.15 | Q9: =SUM(L9:P9) -> 1.65 | R9: =J9*Q9*K9 -> 8.25 | S9: =PI()*(E9/1000)^2*0.25*1*7850 -> 0.88781408 | T9: =R9*S9 -> 7.3244662 | Y9: C1* | Z9: Neck Column | AA9: Vertical Bars | AB9: 16 | AC9: as shown | AD9: 0.4 | AE9: 0.25 | AF9: 1.5 | AG9: 6 | AH9: 1 | AI9: =AF9-0.075 -> 1.425 | AJ9: =16*(AB9/1000) -> 0.256 | AN9: =SUM(AI9:AM9) -> 1.681 | AO9: =AG9*AN9*AH9 -> 10.086 | AP9: =PI()*(AB9/1000)^2*0.25*1*7850 -> 1.5783361 | AQ9: =AO9*AP9 -> 15.919098 | AV9: Column Ties Main Bars | AW9: 10 | AX9: 200 | AY9: 2.5 | AZ9: 0.3 | BA9: 1.5 | BB9: =ROUND(((1.5-0.075)/(AX9/1000))+1,0) -> 8 | BC9: 1 | BD9: =AY9-0.04*2 -> 2.42 | BE9: =AZ9-0.04*2 -> 0.22 | BF9: =BD9 -> 2.42 | BG9: =BE9 -> 0.22 | BH9: =10*(AW9/1000) -> 0.1 | BI9: =SUM(BD9:BH9) -> 5.38 | BJ9: =BB9*BI9*BC9 -> 43.04 | BK9: =PI()*(AW9/1000)^2*0.25*1*7850 -> 0.61653756 | BL9: =BJ9*BK9 -> 26.535777 | BQ9: Side Bars | BR9: 12 | BS9: 0 | BT9: 0.4 | BU9: 0.25 | BV9: 4.9 | BW9: 2 | BX9: 1 | BY9: =BV9 -> 4.9 | CD9: =SUM(BY9:CC9) -> 4.9 | CE9: =BW9*CD9*BX9 -> 9.8 | CF9: =PI()*(BR9/1000)^2*0.25*1*7850 -> 0.88781408 | CG9: =CE9*CF9 -> 8.700578 | CJ9: SUMMARY | DG9: Vertical | DH9: 16 | DI9: 150 | DJ9: 1.2 | DL9: 37.2 | DM9: 36 | DN9: 2 | DO9: =DJ9 -> 1.2 | DP9: =DP8 -> 0.35 | DQ9: =DQ8 -> 0.525 | DT9: =SUM(DO9:DS9) -> 2.075 | DU9: =DM9*DT9*DN9 -> 149.4 | DV9: =PI()*(DH9/1000)^2*0.25*1*7850 -> 1.5783361 | DW9: =DU9*DV9 -> 235.80342
D10: At Long Span (Top) | E10: 12 | F10: 250 | G10: 1.2 | H10: 1.5 | I10: 0.3 | J10: =ROUND(((H10-0.075*2)/(F10/1000))+1,0) -> 6 | K10: 1 | L10: =I10-0.075*2 -> 0.15 | M10: =G10-0.075*2 -> 1.05 | N10: =L10 -> 0.15 | Q10: =SUM(L10:P10) -> 1.35 | R10: =J10*Q10*K10 -> 8.1 | S10: =PI()*(E10/1000)^2*0.25*1*7850 -> 0.88781408 | T10: =R10*S10 -> 7.1912941 | AA10: Column Ties | AB10: 10 | AC10: 200 | AD10: 0.4 | AE10: 0.25 | AF10: 1.5 | AG10: =ROUND(((1.5-0.075)/(AC10/1000))+1,0) -> 8 | AH10: 1 | AI10: =AD10-0.04*2 -> 0.32 | AJ10: =AE10-0.04*2 -> 0.17 | AK10: =AI10 -> 0.32 | AL10: =AJ10 -> 0.17 | AM10: =10*(AB10/1000) -> 0.1 | AN10: =SUM(AI10:AM10) -> 1.08 | AO10: =AG10*AN10*AH10 -> 8.64 | AP10: =PI()*(AB10/1000)^2*0.25*1*7850 -> 0.61653756 | AQ10: =AO10*AP10 -> 5.3268845 | AV10: Column Ties Main Bars | AW10: 10 | AX10: 200 | AY10: 0.55 | AZ10: 0.3 | BA10: 1.5 | BB10: =ROUND(((1.5-0.075)/(AX10/1000))+1,0) -> 8 | BC10: 2 | BD10: =AY10-0.04 -> 0.51 | BE10: =AZ10-0.04*2 -> 0.22 | BF10: =BD10 -> 0.51 | BG10: =BE10 -> 0.22 | BH10: =10*(AW10/1000) -> 0.1 | BI10: =SUM(BD10:BH10) -> 1.56 | BJ10: =BB10*BI10*BC10 -> 24.96 | BK10: =PI()*(AW10/1000)^2*0.25*1*7850 -> 0.61653756 | BL10: =BJ10*BK10 -> 15.388777 | BO10: GB-2 | BP10: Grade Beam | BQ10: Bottom Bars | BR10: 16 | BS10: 0 | BT10: 0.3 | BU10: 0.82 | BV10: 3.55 | BW10: 4 | BX10: 1 | BY10: =BV10 -> 3.55 | CD10: =SUM(BY10:CC10) -> 3.55 | CE10: =BW10*CD10*BX10 -> 14.2 | CF10: =PI()*(BR10/1000)^2*0.25*1*7850 -> 1.5783361 | CG10: =CE10*CF10 -> 22.412373 | CJ10: WATER TANK | CK10: WEIGHT | CL10: LENGTH | CM10: Total Weight | DG10: Link | DH10: 12 | DI10: 150 | DJ10: 1.2 | DK10: 0.25 | DL10: 2.35 | DM10: =ROUND((DJ10/(DI10/1000))+1,0) -> 9 | DN10: 2 | DO10: =DL10-0.05*2 -> 2.25 | DP10: =DK10-0.05*2 -> 0.15 | DQ10: =DO10 -> 2.25 | DR10: =DP10 -> 0.15 | DT10: =SUM(DO10:DS10) -> 4.8 | DU10: =DM10*DT10*DN10 -> 86.4 | DV10: =PI()*(DH10/1000)^2*0.25*1*7850 -> 0.88781408 | DW10: =DU10*DV10 -> 76.707137
B11: F-02 | C11: Isolated Footing | D11: At Short Span (Bottom) | E11: 12 | F11: 200 | G11: 1.3 | H11: 1.7 | I11: 0.3 | J11: =ROUND(((G11-0.075*2)/(F11/1000))+1,0) -> 7 | K11: 1 | L11: =I11-0.075*2 -> 0.15 | M11: =H11-0.075*2 -> 1.55 | N11: =L11 -> 0.15 | Q11: =SUM(L11:P11) -> 1.85 | R11: =J11*Q11*K11 -> 12.95 | S11: =PI()*(E11/1000)^2*0.25*1*7850 -> 0.88781408 | T11: =R11*S11 -> 11.497192 | Y11: C2 | Z11: Neck Column | AA11: Vertical Bars | AB11: 25 | AC11: as shown | AD11: 0.8 | AE11: 0.25 | AF11: 1.5 | AG11: 10 | AH11: 1 | AI11: =AF11-0.075 -> 1.425 | AJ11: =16*(AB11/1000) -> 0.4 | AN11: =SUM(AI11:AM11) -> 1.825 | AO11: =AG11*AN11*AH11 -> 18.25 | AP11: =PI()*(AB11/1000)^2*0.25*1*7850 -> 3.8533597 | AQ11: =AO11*AP11 -> 70.323815 | AV11: C Bar Main Bars | AW11: 10 | AX11: 200 | AY11: 0.55 | AZ11: 0.3 | BA11: 1.5 | BB11: =ROUND(((1.5-0.075)/(AX11/1000))+1,0) -> 8 | BC11: 2 | BD11: 0.1 | BE11: =AZ11-0.04*2 -> 0.22 | BF11: 0.1 | BI11: =SUM(BD11:BH11) -> 0.42 | BJ11: =BB11*BI11*BC11 -> 6.72 | BK11: =PI()*(AW11/1000)^2*0.25*1*7850 -> 0.61653756 | BL11: =BJ11*BK11 -> 4.1431324 | BQ11: Top Bars | BR11: 16 | BS11: 0 | BT11: =BT10 -> 0.3 | BU11: =BU10 -> 0.82 | BV11: 3.55 | BW11: 6 | BX11: 1 | BY11: =BV11 -> 3.55 | CD11: =SUM(BY11:CC11) -> 3.55 | CE11: =BW11*CD11*BX11 -> 21.3 | CF11: =PI()*(BR11/1000)^2*0.25*1*7850 -> 1.5783361 | CG11: =CE11*CF11 -> 33.61856 | CJ11: Water Tank | CK11: =DB6+DB7 -> 2872.7326 | CL11: 1 | CM11: =CK11*CL11*1.1 -> 3160.0058 | DG11: Link | DH11: 12 | DI11: 150 | DJ11: 1.2 | DK11: 0.25 | DL11: 2.125 | DM11: =ROUND((DJ11/(DI11/1000))+1,0) -> 9 | DN11: 2 | DO11: =DL11-0.05*2 -> 2.025 | DP11: =DK11-0.05*2 -> 0.15 | DQ11: =DO11 -> 2.025 | DR11: =DP11 -> 0.15 | DT11: =SUM(DO11:DS11) -> 4.35 | DU11: =DM11*DT11*DN11 -> 78.3 | DV11: =PI()*(DH11/1000)^2*0.25*1*7850 -> 0.88781408 | DW11: =DU11*DV11 -> 69.515843
D12: At Long Span (Bottom) | E12: 12 | F12: 200 | G12: 1.3 | H12: 1.7 | I12: 0.3 | J12: =ROUND(((H12-0.075*2)/(F12/1000))+1,0) -> 9 | K12: 1 | L12: =I12-0.075*2 -> 0.15 | M12: =G12-0.075*2 -> 1.15 | N12: =L12 -> 0.15 | Q12: =SUM(L12:P12) -> 1.45 | R12: =J12*Q12*K12 -> 13.05 | S12: =PI()*(E12/1000)^2*0.25*1*7850 -> 0.88781408 | T12: =R12*S12 -> 11.585974 | AA12: Column Ties | AB12: 10 | AC12: 200 | AD12: 0.8 | AE12: 0.25 | AF12: 1.5 | AG12: =ROUND(((1.5-0.075)/(AC12/1000))+1,0) -> 8 | AH12: 1 | AI12: =AD12-0.04*2 -> 0.72 | AJ12: =AE12-0.04*2 -> 0.17 | AK12: =AI12 -> 0.72 | AL12: =AJ12 -> 0.17 | AM12: =10*(AB12/1000) -> 0.1 | AN12: =SUM(AI12:AM12) -> 1.88 | AO12: =AG12*AN12*AH12 -> 15.04 | AP12: =PI()*(AB12/1000)^2*0.25*1*7850 -> 0.61653756 | AQ12: =AO12*AP12 -> 9.2727249 | AV12: C Bars Intermediatte | AW12: 10 | AX12: 400 | AY12: 0.55 | AZ12: 0.3 | BA12: 1.5 | BB12: =BB11 -> 8 | BC12: 3 | BD12: 0.1 | BE12: =AZ12-0.04*2 -> 0.22 | BF12: 0.1 | BI12: =SUM(BD12:BH12) -> 0.42 | BJ12: =BB12*BI12*BC12 -> 10.08 | BK12: =PI()*(AW12/1000)^2*0.25*1*7850 -> 0.61653756 | BL12: =BJ12*BK12 -> 6.2146986 | BQ12: Links | BR12: 10 | BS12: 250 | BT12: =BT11 -> 0.3 | BU12: =BU11 -> 0.82 | BV12: 3.55 | BW12: =ROUND((BV12/(BS12/1000))+1,0) -> 15 | BX12: 1 | BY12: =BT12-0.04*2 -> 0.22 | BZ12: =BU12-0.04*2 -> 0.74 | CA12: =BY12 -> 0.22 | CB12: =BZ12 -> 0.74 | CC12: =(10*BR12)/1000 -> 0.1 | CD12: =SUM(BY12:CC12) -> 2.02 | CE12: =BW12*CD12*BX12 -> 30.3 | CF12: =PI()*(BR12/1000)^2*0.25*1*7850 -> 0.61653756 | CG12: =CE12*CF12 -> 18.681088 | CJ12: WALL | CM12: =SUM(CM11:CM11) -> 3160.0058 | DG12: Link 1 | DH12: 12 | DI12: 150 | DJ12: 1.2 | DK12: 0.25 | DL12: 2.125 | DM12: =ROUND((DJ12/(DI12/1000))+1,0) -> 9 | DN12: 4 | DO12: 0.67 | DP12: =DK12-0.05*2 -> 0.15 | DQ12: =DO12 -> 0.67 | DR12: =DP12 -> 0.15 | DT12: =SUM(DO12:DS12) -> 1.64 | DU12: =DM12*DT12*DN12 -> 59.04 | DV12: =PI()*(DH12/1000)^2*0.25*1*7850 -> 0.88781408 | DW12: =DU12*DV12 -> 52.416544
D13: At Short Span (Top) | E13: 12 | F13: 250 | G13: 1.3 | H13: 1.7 | I13: 0.3 | J13: =ROUND(((G13-0.075*2)/(F13/1000))+1,0) -> 6 | K13: 1 | L13: =I13-0.075*2 -> 0.15 | M13: =H13-0.075*2 -> 1.55 | N13: =L13 -> 0.15 | Q13: =SUM(L13:P13) -> 1.85 | R13: =J13*Q13*K13 -> 11.1 | S13: =PI()*(E13/1000)^2*0.25*1*7850 -> 0.88781408 | T13: =R13*S13 -> 9.8547363 | AA13: Column Ties | AB13: 10 | AC13: 200 | AD13: 0.8 | AE13: 0.25 | AF13: 1.5 | AG13: =ROUND(((1.5-0.075)/(AC13/1000))+1,0) -> 8 | AH13: 1 | AI13: =10*(AB13/1000) -> 0.1 | AJ13: =AE13-0.04*2 -> 0.17 | AK13: =AI13 -> 0.1 | AN13: =SUM(AI13:AM13) -> 0.37 | AO13: =AG13*AN13*AH13 -> 2.96 | AP13: =PI()*(AB13/1000)^2*0.25*1*7850 -> 0.61653756 | AQ13: =AO13*AP13 -> 1.8249512 | AT13: W2 | AU13: Shear Wall | AV13: Main Vertical Bars | AW13: 16 | AX13: as shown | BA13: 1.5 | BB13: 4 | BC13: 2 | BD13: =BA13-0.075*2 -> 1.35 | BE13: =16*(AW13/1000) -> 0.256 | BI13: =SUM(BD13:BH13) -> 1.606 | BJ13: =BB13*BI13*BC13 -> 12.848 | BK13: =PI()*(AW13/1000)^2*0.25*1*7850 -> 1.5783361 | BL13: =BJ13*BK13 -> 20.278463 | BQ13: Side Bars | BR13: 12 | BS13: =BS11 -> 0 | BT13: 0.4 | BU13: 0.25 | BV13: =BV12 -> 3.55 | BW13: 2 | BX13: 1 | BY13: =BV13 -> 3.55 | CD13: =SUM(BY13:CC13) -> 3.55 | CE13: =BW13*CD13*BX13 -> 7.1 | CF13: =PI()*(BR13/1000)^2*0.25*1*7850 -> 0.88781408 | CG13: =CE13*CF13 -> 6.30348 | DG13: Link 2 | DH13: 12 | DI13: 150 | DJ13: 1.2 | DK13: 0.25 | DL13: 2.125 | DM13: =ROUND((DJ13/(DI13/1000))+1,0) -> 9 | DN13: 4 | DO13: 0.5 | DP13: =DK13-0.05*2 -> 0.15 | DQ13: =DO13 -> 0.5 | DR13: =DP13 -> 0.15 | DT13: =SUM(DO13:DS13) -> 1.3 | DU13: =DM13*DT13*DN13 -> 46.8 | DV13: =PI()*(DH13/1000)^2*0.25*1*7850 -> 0.88781408 | DW13: =DU13*DV13 -> 41.549699
D14: At Long Span (Top) | E14: 12 | F14: 250 | G14: 1.3 | H14: 1.7 | I14: 0.3 | J14: =ROUND(((H14-0.075*2)/(F14/1000))+1,0) -> 7 | K14: 1 | L14: =I14-0.075*2 -> 0.15 | M14: =G14-0.075*2 -> 1.15 | N14: =L14 -> 0.15 | Q14: =SUM(L14:P14) -> 1.45 | R14: =J14*Q14*K14 -> 10.15 | S14: =PI()*(E14/1000)^2*0.25*1*7850 -> 0.88781408 | T14: =R14*S14 -> 9.011313 | Y14: C3 | Z14: Neck Column | AA14: Vertical Bars | AB14: 16 | AC14: as shown | AD14: 0.8 | AE14: 0.25 | AF14: 1.5 | AG14: 12 | AH14: 1 | AI14: =AF14-0.075 -> 1.425 | AJ14: =16*(AB14/1000) -> 0.256 | AN14: =SUM(AI14:AM14) -> 1.681 | AO14: =AG14*AN14*AH14 -> 20.172 | AP14: =PI()*(AB14/1000)^2*0.25*1*7850 -> 1.5783361 | AQ14: =AO14*AP14 -> 31.838197 | AV14: Intermediate Vertical Bars | AW14: 12 | AX14: as shown | BA14: 1.5 | BB14: 10 | BC14: 1 | BD14: =BA14-0.075*2 -> 1.35 | BE14: =16*(AW14/1000) -> 0.192 | BI14: =SUM(BD14:BH14) -> 1.542 | BJ14: =BB14*BI14*BC14 -> 15.42 | BK14: =PI()*(AW14/1000)^2*0.25*1*7850 -> 0.88781408 | BL14: =BJ14*BK14 -> 13.690093 | BO14: GB-3 | BP14: Grade Beam | BQ14: Bottom Bars | BR14: 16 | BS14: 0 | BT14: 0.25 | BU14: 0.82 | BV14: 2.93 | BW14: 2 | BX14: 1 | BY14: =BV14 -> 2.93 | CD14: =SUM(BY14:CC14) -> 2.93 | CE14: =BW14*CD14*BX14 -> 5.86 | CF14: =PI()*(BR14/1000)^2*0.25*1*7850 -> 1.5783361 | CG14: =CE14*CF14 -> 9.2490498 | DG14: C- Bars | DH14: 8 | DI14: 400 | DJ14: 1.2 | DK14: 0.25 | DL14: 2.125 | DM14: =ROUND((DJ14/(DI14/1000))+1,0) -> 4 | DN14: 18 | DO14: 0.17 | DP14: =0.1 -> 0.1 | DR14: =DP14 -> 0.1 | DT14: =SUM(DO14:DS14) -> 0.37 | DU14: =DM14*DT14*DN14 -> 26.64 | DV14: =PI()*(DH14/1000)^2*0.25*1*7850 -> 0.39458404 | DW14: =DU14*DV14 -> 10.511719
B15: F-03 | C15: Isolated Footing | D15: At Short Span (Bottom) | E15: 12 | F15: 200 | G15: 1.4 | H15: 1.7 | I15: 0.3 | J15: =ROUND(((G15-0.075*2)/(F15/1000))+1,0) -> 7 | K15: 1 | L15: =I15-0.075*2 -> 0.15 | M15: =H15-0.075*2 -> 1.55 | N15: =L15 -> 0.15 | Q15: =SUM(L15:P15) -> 1.85 | R15: =J15*Q15*K15 -> 12.95 | S15: =PI()*(E15/1000)^2*0.25*1*7850 -> 0.88781408 | T15: =R15*S15 -> 11.497192 | AA15: Column Ties | AB15: 10 | AC15: 200 | AD15: 0.8 | AE15: 0.25 | AF15: 1.5 | AG15: =ROUND(((1.5-0.075)/(AC15/1000))+1,0) -> 8 | AH15: 1 | AI15: =AD15-0.04*2 -> 0.72 | AJ15: =AE15-0.04*2 -> 0.17 | AK15: =AI15 -> 0.72 | AL15: =AJ15 -> 0.17 | AM15: =10*(AB15/1000) -> 0.1 | AN15: =SUM(AI15:AM15) -> 1.88 | AO15: =AG15*AN15*AH15 -> 15.04 | AP15: =PI()*(AB15/1000)^2*0.25*1*7850 -> 0.61653756 | AQ15: =AO15*AP15 -> 9.2727249 | AV15: Column Ties Main Bars | AW15: 10 | AX15: 200 | BA15: 1.5 | BB15: =ROUND(((1.5-0.075)/(AX15/1000))+1,0) -> 8 | BC15: 2 | BD15: 0.17 | BE15: 0.17 | BF15: =BD15 -> 0.17 | BG15: =BE15 -> 0.17 | BH15: =10*(AW15/1000) -> 0.1 | BI15: =SUM(BD15:BH15) -> 0.78 | BJ15: =BB15*BI15*BC15 -> 12.48 | BK15: =PI()*(AW15/1000)^2*0.25*1*7850 -> 0.61653756 | BL15: =BJ15*BK15 -> 7.6943887 | BQ15: Top Bars | BR15: 16 | BS15: 0 | BT15: 0.25 | BU15: 0.82 | BV15: 2.93 | BW15: 6 | BX15: 1 | BY15: =BV15 -> 2.93 | CD15: =SUM(BY15:CC15) -> 2.93 | CE15: =BW15*CD15*BX15 -> 17.58 | CF15: =PI()*(BR15/1000)^2*0.25*1*7850 -> 1.5783361 | CG15: =CE15*CF15 -> 27.74715
D16: At Long Span (Bottom) | E16: 12 | F16: 200 | G16: 1.4 | H16: 1.7 | I16: 0.3 | J16: =ROUND(((H16-0.075*2)/(F16/1000))+1,0) -> 9 | K16: 1 | L16: =I16-0.075*2 -> 0.15 | M16: =G16-0.075*2 -> 1.25 | N16: =L16 -> 0.15 | Q16: =SUM(L16:P16) -> 1.55 | R16: =J16*Q16*K16 -> 13.95 | S16: =PI()*(E16/1000)^2*0.25*1*7850 -> 0.88781408 | T16: =R16*S16 -> 12.385006 | AA16: Column Ties | AB16: 10 | AC16: 200 | AD16: 0.8 | AE16: 0.25 | AF16: 1.5 | AG16: =ROUND(((1.5-0.075)/(AC16/1000))+1,0) -> 8 | AH16: 1 | AI16: =AL16 -> 0.17 | AJ16: =AE16-0.04*2 -> 0.17 | AK16: =AI16 -> 0.17 | AL16: =AJ16 -> 0.17 | AM16: =10*(AB16/1000) -> 0.1 | AN16: =SUM(AI16:AM16) -> 0.78 | AO16: =AG16*AN16*AH16 -> 6.24 | AP16: =PI()*(AB16/1000)^2*0.25*1*7850 -> 0.61653756 | AQ16: =AO16*AP16 -> 3.8471944 | AV16: Column Ties Main Bars | AW16: 10 | AX16: 200 | AY16: 1.3 | AZ16: 0.25 | BA16: 1.5 | BB16: =ROUND(((1.5-0.075)/(AX16/1000))+1,0) -> 8 | BC16: 1 | BD16: =AY16-0.04*2 -> 1.22 | BE16: =AZ16-0.04*2 -> 0.17 | BF16: =BD16 -> 1.22 | BG16: =BE16 -> 0.17 | BH16: =10*(AW16/1000) -> 0.1 | BI16: =SUM(BD16:BH16) -> 2.88 | BJ16: =BB16*BI16*BC16 -> 23.04 | BK16: =PI()*(AW16/1000)^2*0.25*1*7850 -> 0.61653756 | BL16: =BJ16*BK16 -> 14.205025 | BQ16: Links | BR16: 10 | BS16: 150 | BT16: 0.25 | BU16: 0.82 | BV16: 2.93 | BW16: =ROUND((BV16/(BS16/1000))+1,0) -> 21 | BX16: 1 | BY16: =BT16-0.04*2 -> 0.17 | BZ16: =BU16-0.04*2 -> 0.74 | CA16: =BY16 -> 0.17 | CB16: =BZ16 -> 0.74 | CC16: =(10*BR16)/1000 -> 0.1 | CD16: =SUM(BY16:CC16) -> 1.92 | CE16: =BW16*CD16*BX16 -> 40.32 | CF16: =PI()*(BR16/1000)^2*0.25*1*7850 -> 0.61653756 | CG16: =CE16*CF16 -> 24.858794 | DE16: SUMMARY | DY16: SUMMARY
D17: At Short Span (Top) | E17: 12 | F17: 250 | G17: 1.4 | H17: 1.7 | I17: 0.3 | J17: =ROUND(((G17-0.075*2)/(F17/1000))+1,0) -> 6 | K17: 1 | L17: =I17-0.075*2 -> 0.15 | M17: =H17-0.075*2 -> 1.55 | N17: =L17 -> 0.15 | Q17: =SUM(L17:P17) -> 1.85 | R17: =J17*Q17*K17 -> 11.1 | S17: =PI()*(E17/1000)^2*0.25*1*7850 -> 0.88781408 | T17: =R17*S17 -> 9.8547363 | Y17: C4 | Z17: Neck Column | AA17: Vertical Bars | AB17: 16 | AC17: as shown | AD17: 0.6 | AE17: 0.25 | AF17: 1.5 | AG17: 10 | AH17: 1 | AI17: =AF17-0.075 -> 1.425 | AJ17: =16*(AB17/1000) -> 0.256 | AN17: =SUM(AI17:AM17) -> 1.681 | AO17: =AG17*AN17*AH17 -> 16.81 | AP17: =PI()*(AB17/1000)^2*0.25*1*7850 -> 1.5783361 | AQ17: =AO17*AP17 -> 26.531831 | AV17: C Bars Intermediatte | AW17: 10 | AX17: 200 | AY17: 0.55 | AZ17: 0.3 | BA17: 1.5 | BB17: =ROUND(((1.5-0.075)/(AX17/1000))+1,0) -> 8 | BC17: 2 | BD17: 0.1 | BE17: =AZ17-0.04*2 -> 0.22 | BF17: 0.1 | BI17: =SUM(BD17:BH17) -> 0.42 | BJ17: =BB17*BI17*BC17 -> 6.72 | BK17: =PI()*(AW17/1000)^2*0.25*1*7850 -> 0.61653756 | BL17: =BJ17*BK17 -> 4.1431324 | BQ17: Side Bars | BR17: 12 | BS17: 0 | BT17: 0.4 | BU17: 0.25 | BV17: =BV16 -> 2.93 | BW17: 2 | BX17: 1 | BY17: =BV17 -> 2.93 | CD17: =SUM(BY17:CC17) -> 2.93 | CE17: =BW17*CD17*BX17 -> 5.86 | CF17: =PI()*(BR17/1000)^2*0.25*1*7850 -> 0.88781408 | CG17: =CE17*CF17 -> 5.2025905 | DE17: WATER TANK | DF17: WEIGHT | DG17: LENGTH | DH17: Total Weight | DY17: WATER TANK | DZ17: WEIGHT | EA17: AREA | EB17: Total Weight
